Workbook
Name AsistenteDesdeSalones: Supuestos!$B$72
Name CapitalInicial: Supuestos!$B$63
Name CaracteresPorRespuesta: Supuestos!$B$41
Name CargasSociales: Supuestos!$B$74
Name CobroInstalacion: Supuestos!$B$64
Name Colchon: Supuestos!$B$7
Name ComisionCobro: Supuestos!$B$10
Name ComisionOpenRouter: Supuestos!$B$22
Name CompraEquipo: Supuestos!$B$84
Name Contador: Supuestos!$B$79
Name CostoHoraSoporte: Supuestos!$B$50
Name CostoIAPorMensaje: Supuestos!$B$23
Name CostoTranscripcionPorMensaje: Supuestos!$B$30
Name CostoVozPorRespuesta: Supuestos!$B$42
Name CostoYouTube: Supuestos!$B$57
Name CuotaYouTube: Supuestos!$B$58
Name FactorCambio: Supuestos!$B$53
Name FactorNeto: Supuestos!$B$54
Name FijoN8n: Supuestos!$B$46
Name FijoOtros: Supuestos!$B$48
Name FijoPorSalon: Supuestos!$B$52
Name FijoServidor: Supuestos!$B$45
Name FijosTotal: Supuestos!$B$51
Name FijoVoz: Supuestos!$B$47
Name GratisPorNumero: Supuestos!$B$34
Name HerramientasUSD: Supuestos!$B$83
Name IncluirAsistente: Supuestos!$B$70
Name IncluirCargas: Supuestos!$B$73
Name IncluirContador: Supuestos!$B$78
Name IncluirHerramientas: Supuestos!$B$82
Name IncluirISR: Supuestos!$B$80
Name IncluirPublicidad: Supuestos!$B$75
Name IncluirSueldo: Supuestos!$B$67
Name IncluyeITBIS: Supuestos!$B$9
Name ITBIS: Supuestos!$B$8
Name LlamadasPorMensaje: Supuestos!$B$19
Name MargenObjetivo: Supuestos!$B$11
Name MensajesPorRespuesta: Supuestos!$B$36
Name MensualidadesComision: Supuestos!$B$77
Name MesEquipo: Supuestos!$B$85
Name MinimoSegundos: Supuestos!$B$28
Name PorcAgrupados: Supuestos!$B$21
Name PorcCache: Supuestos!$B$20
Name PorcNotasVoz: Supuestos!$B$29
Name PrecioCache: Supuestos!$B$16
Name PrecioEntrada: Supuestos!$B$14
Name PrecioSalida: Supuestos!$B$15
Name PrecioTranscripcion: Supuestos!$B$26
Name PrecioVoz: Supuestos!$B$40
Name PrimerMes: Supuestos!$B$62
Name PublicidadMensual: Supuestos!$B$76
Name RespuestasPorMensaje: Supuestos!$B$37
Name SalonesActivos: Supuestos!$B$49
Name SegundosNota: Supuestos!$B$27
Name SueldoAsistente: Supuestos!$B$71
Name TarifaServicio: Supuestos!$B$33
Name TarifaUtilidad: Supuestos!$B$35
Name TasaISR: Supuestos!$B$81
Name TasaUSD: Supuestos!$B$6
Name TokensEntrada: Supuestos!$B$17

Sheet Empieza aquí
B1: Lalan AI · El libro de la empresa
B2: Aquí se ve cuánto entra, cuánto sale y cuánto gana la empresa. Todo se recalcula solo.
A4: Cómo se usa (3 pasos)
B5: 1. Hoja MI EMPRESA: escribe cuántos salones de cada plan entran y cuántos se van cada mes. Los números que hay son un ejemplo.
B6: 2. Hoja RESUMEN: mira si la empresa gana, desde qué mes, y cuánto dinero necesitas para arrancar.
B7: 3. Si quieres probar otra cosa, cambia precios en PLANES, o sueldos, publicidad, dólar… en SUPUESTOS. Cada gasto de la empresa tiene un interruptor: 1 lo incluye, 0 lo quita.
A9: Los colores
B10: Azul con fondo amarillo = lo escribes tú
B11: Negro = se calcula solo (no lo toques)
B12: Verde = viene de otra hoja
B13: Rojo = pérdida o caja negativa
A15: Ejemplo en vivo: un salón del plan Salón al mes
B16: La dueña paga | C16: =Planes!C6 -> 1490
B17: Se va en ITBIS y comisión del cobro | C17: =Planes!C6-Planes!C31 -> 277.79661 | D17: El ITBIS es de la DGII, no tuyo.
B18: Cuesta atenderla (IA, WhatsApp, notas de voz) | C18: =Planes!C27 -> 198.74147 | D18: Se paga en dólares; aquí ya en pesos.
B19: Queda para pagar la empresa y ganar | C19: =Planes!C31-Planes!C27 -> 1013.4619 | D19: Con esto se pagan servidores, sueldos, publicidad… Lo que sobra es ganancia.
A21: Palabras que aparecen
B22: Ingreso neto | C22: Lo cobrado menos el ITBIS y la comisión de la tarjeta. Es el dinero que de verdad es de la empresa.
B23: Costo de atender un salón | C23: Lo que sube con cada salón: la IA, las notas de voz, WhatsApp si lo pagas tú y la voz de la dueña.
B24: Sistema | C24: Lo que pagas igual tengas 1 o 100 salones: servidores, n8n, dominio, la suscripción de voz. La API de YouTube es gratis.
B25: Gastos de la empresa | C25: Tu sueldo, la asistente, publicidad, contador… Se encienden y apagan en Supuestos.
B26: Ganancia | C26: Ingreso neto menos todo lo que sale y el ISR.
B27: Margen | C27: Qué parte del ingreso neto queda de ganancia. 30 % = de cada RD$ 100, quedan RD$ 30.
B28: Caja | C28: El dinero acumulado en la cuenta mes tras mes. Si se pone en rojo, hace falta poner dinero.
B29: Colchón cambiario | C29: Tú cobras en pesos y pagas en dólares; el colchón encarece un poco los costos en dólares por si sube el dólar.
B30: Cuota de YouTube | C30: Google regala 10.000 unidades al día para toda la app; cada búsqueda de música gasta 100. No cuesta dinero, pero se puede acabar.
A32: Las otras hojas
B33: Planes | C33: Precio, costo y margen de UN salón de cada plan.
B34: Supuestos | C34: Precios de proveedores, dólar, impuestos y gastos de la empresa.
B35: Negociación | C35: Para calcular un descuento con un salón concreto.
B36: Sensibilidad | C36: Qué pasa con el margen si sube el dólar o la IA.
B37: Qué incluye | C37: Lo que trae cada plan, para el documento comercial.
B38: Fuentes | C38: De dónde salen los precios.

Sheet Resumen
A1: Lalan AI · Cómo va la empresa
A2: Primer año, según los salones que pusiste en Mi empresa. Esta hoja no se edita: cambia Mi empresa o Supuestos.
A4: Lo importante
A5: Salones pagando al cerrar el año | B5: ='Mi empresa'!N17 -> 52
A6: Ingreso neto del año | B6: ='Mi empresa'!B27 -> 258634.58 | C6: Lo cobrado, sin ITBIS ni comisiones.
A7: Todo lo que salió en el año | B7: ='Mi empresa'!B54 -> 150915.12 | C7: Atender salones + sistema + gastos de la empresa.
A8: Ganancia del año (después de ISR) | B8: ='Mi empresa'!B57 -> 74576.398
A9: Margen del año | B9: ='Mi empresa'!B58 -> 0.28834659 | C9: De cada RD$ 100 que son tuyos, cuánto queda de ganancia.
A10: Ganancia del último mes | B10: ='Mi empresa'!N57 -> 23118.217 | C10: Así queda el negocio al terminar el año.
A11: Primer mes con ganancia | B11: =IFERROR(INDEX('Mi empresa'!$C$4:$N$4,1,MATCH(1,'Mi empresa'!$C$60:$N$60,0)),"Todavía no") -> 46419 | C11: El primer mes en que entra más de lo que sale.
A12: Dinero que necesitas para no quedarte en rojo | B12: =MAX(0,CapitalInicial-MIN('Mi empresa'!$C$59:$N$59)) -> 15032.622 | C12: Lo más hondo que llega la caja. Tenlo guardado o consíguelo antes de empezar.
A13: Caja al final del año | B13: ='Mi empresa'!N59 -> 74576.398
A14: Salones que necesitas para cubrir todos los gastos | B14: =IF(('Mi empresa'!N27-'Mi empresa'!N33)>0,('Mi empresa'!N40+'Mi empresa'!N51-'Mi empresa'!N47)/(('Mi empresa'!N27-'Mi empresa'!N33)/'Mi empresa'!N17),0) -> 11.415911 | C14: Con la mezcla de planes y los gastos del mes 12. Si es mayor que tus salones, todavía pierdes.
A15: Cuota de YouTube usada (mes 12) | B15: ='Mi empresa'!N64 -> 1.95 | C15: La API de YouTube es gratis; el límite es la cuota diaria. Más de 80 %: pide ampliación a Google.
A17: A dónde se va el dinero (año) | B17: RD$ | C17: De cada RD$ 100 de ingreso neto
A18: Atender a los salones (IA, WhatsApp, voz) | B18: ='Mi empresa'!B33 -> 48256.06 | C18: =IF('Mi empresa'!$B$27>0,B18/'Mi empresa'!$B$27*100,0) -> 18.658008
A19: Sistema (servidores, voz, YouTube) | B19: ='Mi empresa'!B40 -> 51246.558 | C19: =IF('Mi empresa'!$B$27>0,B19/'Mi empresa'!$B$27*100,0) -> 19.814272
A20: Sueldos y cargas sociales | B20: ='Mi empresa'!B43+'Mi empresa'!B44+'Mi empresa'!B45 -> 0 | C20: =IF('Mi empresa'!$B$27>0,B20/'Mi empresa'!$B$27*100,0) -> 0
A21: Publicidad y comisiones | B21: ='Mi empresa'!B46+'Mi empresa'!B47 -> 36000 | C21: =IF('Mi empresa'!$B$27>0,B21/'Mi empresa'!$B$27*100,0) -> 13.919253
A22: Contador, herramientas y equipo | B22: ='Mi empresa'!B48+'Mi empresa'!B49+'Mi empresa'!B50 -> 15412.499 | C22: =IF('Mi empresa'!$B$27>0,B22/'Mi empresa'!$B$27*100,0) -> 5.9591795
A23: ISR | B23: ='Mi empresa'!B56 -> 33143.062 | C23: =IF('Mi empresa'!$B$27>0,B23/'Mi empresa'!$B$27*100,0) -> 12.814629
A24: Te queda de ganancia | B24: ='Mi empresa'!B57 -> 74576.398 | C24: =IF('Mi empresa'!$B$27>0,B24/'Mi empresa'!$B$27*100,0) -> 28.834659
A26: Mes a mes
A27: Mes | B27: Salones | C27: Ingreso neto | D27: Todo lo que sale | E27: Ganancia | F27: Caja
A28: ='Mi empresa'!C4 -> 46296 | B28: ='Mi empresa'!C17 -> 2 | C28: ='Mi empresa'!C27 -> 1614.9153 | D28: ='Mi empresa'!C54 -> 7755.8842 | E28: ='Mi empresa'!C57 -> -6140.969 | F28: ='Mi empresa'!C59 -> -6140.969
A29: ='Mi empresa'!D4 -> 46327 | B29: ='Mi empresa'!D17 -> 4 | C29: ='Mi empresa'!D27 -> 3229.8305 | D29: ='Mi empresa'!D54 -> 8016.4564 | E29: ='Mi empresa'!D57 -> -4786.6259 | F29: ='Mi empresa'!D59 -> -10927.595
A30: ='Mi empresa'!E4 -> 46357 | B30: ='Mi empresa'!E17 -> 7 | C30: ='Mi empresa'!E27 -> 5247.4576 | D30: ='Mi empresa'!E54 -> 8338.8592 | E30: ='Mi empresa'!E57 -> -3091.4016 | F30: ='Mi empresa'!E59 -> -14018.996
A31: ='Mi empresa'!F4 -> 46388 | B31: ='Mi empresa'!F17 -> 11 | C31: ='Mi empresa'!F27 -> 9697.6271 | D31: ='Mi empresa'!F54 -> 10711.253 | E31: ='Mi empresa'!F57 -> -1013.6254 | F31: ='Mi empresa'!F59 -> -15032.622
A32: ='Mi empresa'!G4 -> 46419 | B32: ='Mi empresa'!G17 -> 14 | C32: ='Mi empresa'!G27 -> 12524.746 | D32: ='Mi empresa'!G54 -> 11170.566 | E32: ='Mi empresa'!G57 -> 988.55111 | F32: ='Mi empresa'!G59 -> -14044.071
A33: ='Mi empresa'!H4 -> 46447 | B33: ='Mi empresa'!H17 -> 19 | C33: ='Mi empresa'!H27 -> 18187.119 | D33: ='Mi empresa'!H54 -> 12328.889 | E33: ='Mi empresa'!H57 -> 4276.5079 | F33: ='Mi empresa'!H59 -> -9767.5628
A34: ='Mi empresa'!I4 -> 46478 | B34: ='Mi empresa'!I17 -> 24 | C34: ='Mi empresa'!I27 -> 21819.661 | D34: ='Mi empresa'!I54 -> 12911.864 | E34: ='Mi empresa'!I57 -> 6502.6921 | F34: ='Mi empresa'!I59 -> -3264.8707
A35: ='Mi empresa'!J4 -> 46508 | B35: ='Mi empresa'!J17 -> 29 | C35: ='Mi empresa'!J27 -> 27482.034 | D35: ='Mi empresa'!J54 -> 14070.186 | E35: ='Mi empresa'!J57 -> 9790.649 | F35: ='Mi empresa'!J59 -> 6525.7783
A36: ='Mi empresa'!K4 -> 46539 | B36: ='Mi empresa'!K17 -> 33 | C36: ='Mi empresa'!K27 -> 29902.373 | D36: ='Mi empresa'!K54 -> 14454.42 | E36: ='Mi empresa'!K57 -> 11277.006 | F36: ='Mi empresa'!K59 -> 17802.784
A37: ='Mi empresa'!L4 -> 46569 | B37: ='Mi empresa'!L17 -> 39 | C37: ='Mi empresa'!L27 -> 35967.458 | D37: ='Mi empresa'!L54 -> 15674.573 | E37: ='Mi empresa'!L57 -> 14813.806 | F37: ='Mi empresa'!L59 -> 32616.59
A38: ='Mi empresa'!M4 -> 46600 | B38: ='Mi empresa'!M17 -> 45 | C38: ='Mi empresa'!M27 -> 42842.034 | D38: ='Mi empresa'!M54 -> 17031.637 | E38: ='Mi empresa'!M57 -> 18841.59 | F38: ='Mi empresa'!M59 -> 51458.18
A39: ='Mi empresa'!N4 -> 46631 | B39: ='Mi empresa'!N17 -> 52 | C39: ='Mi empresa'!N27 -> 50119.322 | D39: ='Mi empresa'!N54 -> 18450.531 | E39: ='Mi empresa'!N57 -> 23118.217 | F39: ='Mi empresa'!N59 -> 74576.398

Sheet Mi empresa
A1: Mi empresa · Lalan AI mes a mes (todo en RD$)
A2: Escribe en AZUL cuántos salones entran y cuántos se van cada mes (los de ahora son un EJEMPLO). Todo lo demás se calcula con las hojas Planes y Supuestos. Pasa el ratón por los nombres de las filas para ver la explicación.
A4: Concepto | B4: Año | C4: =EDATE(PrimerMes,0) -> 46296 | D4: =EDATE(PrimerMes,1) -> 46327 | E4: =EDATE(PrimerMes,2) -> 46357 | F4: =EDATE(PrimerMes,3) -> 46388 | G4: =EDATE(PrimerMes,4) -> 46419 | H4: =EDATE(PrimerMes,5) -> 46447 | I4: =EDATE(PrimerMes,6) -> 46478 | J4: =EDATE(PrimerMes,7) -> 46508 | K4: =EDATE(PrimerMes,8) -> 46539 | L4: =EDATE(PrimerMes,9) -> 46569 | M4: =EDATE(PrimerMes,10) -> 46600 | N4: =EDATE(PrimerMes,11) -> 46631
A5: Mes n.º | C5: 1 | D5: 2 | E5: 3 | F5: 4 | G5: 5 | H5: 6 | I5: 7 | J5: 8 | K5: 9 | L5: 10 | M5: 11 | N5: 12
A7: Salones
A8: Salones nuevos · Esencial | B8: =SUM(C8:N8) -> 28 | C8: 1 | D8: 1 | E8: 2 | F8: 2 | G8: 2 | H8: 2 | I8: 3 | J8: 3 | K8: 3 | L8: 3 | M8: 3 | N8: 3
A9: Salones nuevos · Salón | B9: =SUM(C9:N9) -> 22 | C9: 1 | D9: 1 | E9: 1 | F9: 1 | G9: 2 | H9: 2 | I9: 2 | J9: 2 | K9: 2 | L9: 2 | M9: 3 | N9: 3
A10: Salones nuevos · Lounge | B10: =SUM(C10:N10) -> 6 | C10: 0 | D10: 0 | E10: 0 | F10: 1 | G10: 0 | H10: 1 | I10: 0 | J10: 1 | K10: 0 | L10: 1 | M10: 1 | N10: 1
A11: Salones que se van · Esencial | B11: =SUM(C11:N11) -> 3 | C11: 0 | D11: 0 | E11: 0 | F11: 0 | G11: 1 | H11: 0 | I11: 0 | J11: 1 | K11: 0 | L11: 0 | M11: 1 | N11: 0
A12: Salones que se van · Salón | B12: =SUM(C12:N12) -> 1 | C12: 0 | D12: 0 | E12: 0 | F12: 0 | G12: 0 | H12: 0 | I12: 0 | J12: 0 | K12: 1 | L12: 0 | M12: 0 | N12: 0
A13: Salones que se van · Lounge | B13: =SUM(C13:N13) -> 0 | C13: 0 | D13: 0 | E13: 0 | F13: 0 | G13: 0 | H13: 0 | I13: 0 | J13: 0 | K13: 0 | L13: 0 | M13: 0 | N13: 0
A14: Salones pagando · Esencial | B14: =N14 -> 25 | C14: =MAX(0,C8-C11) -> 1 | D14: =MAX(0,C14+D8-D11) -> 2 | E14: =MAX(0,D14+E8-E11) -> 4 | F14: =MAX(0,E14+F8-F11) -> 6 | G14: =MAX(0,F14+G8-G11) -> 7 | H14: =MAX(0,G14+H8-H11) -> 9 | I14: =MAX(0,H14+I8-I11) -> 12 | J14: =MAX(0,I14+J8-J11) -> 14 | K14: =MAX(0,J14+K8-K11) -> 17 | ... N14: =MAX(0,M14+N8-N11) -> 25
A15: Salones pagando · Salón | B15: =N15 -> 21 | C15: =MAX(0,C9-C12) -> 1 | D15: =MAX(0,C15+D9-D12) -> 2 | E15: =MAX(0,D15+E9-E12) -> 3 | F15: =MAX(0,E15+F9-F12) -> 4 | G15: =MAX(0,F15+G9-G12) -> 6 | H15: =MAX(0,G15+H9-H12) -> 8 | I15: =MAX(0,H15+I9-I12) -> 10 | J15: =MAX(0,I15+J9-J12) -> 12 | K15: =MAX(0,J15+K9-K12) -> 13 | ... N15: =MAX(0,M15+N9-N12) -> 21
A16: Salones pagando · Lounge | B16: =N16 -> 6 | C16: =MAX(0,C10-C13) -> 0 | D16: =MAX(0,C16+D10-D13) -> 0 | E16: =MAX(0,D16+E10-E13) -> 0 | F16: =MAX(0,E16+F10-F13) -> 1 | G16: =MAX(0,F16+G10-G13) -> 1 | H16: =MAX(0,G16+H10-H13) -> 2 | I16: =MAX(0,H16+I10-I13) -> 2 | J16: =MAX(0,I16+J10-J13) -> 3 | K16: =MAX(0,J16+K10-K13) -> 3 | ... N16: =MAX(0,M16+N10-N13) -> 6
A17: SALONES PAGANDO | B17: =N17 -> 52 | C17: =C14+C15+C16 -> 2 | D17: =D14+D15+D16 -> 4 | E17: =E14+E15+E16 -> 7 | F17: =F14+F15+F16 -> 11 | G17: =G14+G15+G16 -> 14 | H17: =H14+H15+H16 -> 19 | I17: =I14+I15+I16 -> 24 | J17: =J14+J15+J16 -> 29 | ... N17: =N14+N15+N16 -> 52
A19: Lo que entra
A20: Mensualidades · Esencial | B20: =SUM(C20:N20) -> 68805 | C20: =C14*Planes!$B$6 -> 495 | D20: =D14*Planes!$B$6 -> 990 | E20: =E14*Planes!$B$6 -> 1980 | F20: =F14*Planes!$B$6 -> 2970 | G20: =G14*Planes!$B$6 -> 3465 | H20: =H14*Planes!$B$6 -> 4455 | I20: =I14*Planes!$B$6 -> 5940 | J20: =J14*Planes!$B$6 -> 6930 | ... N20: =N14*Planes!$B$6 -> 12375
A21: Mensualidades · Salón | B21: =SUM(C21:N21) -> 168370 | C21: =C15*Planes!$C$6 -> 1490 | D21: =D15*Planes!$C$6 -> 2980 | E21: =E15*Planes!$C$6 -> 4470 | F21: =F15*Planes!$C$6 -> 5960 | G21: =G15*Planes!$C$6 -> 8940 | H21: =H15*Planes!$C$6 -> 11920 | I21: =I15*Planes!$C$6 -> 14900 | J21: =J15*Planes!$C$6 -> 17880 | ... N21: =N15*Planes!$C$6 -> 31290
A22: Mensualidades · Lounge | B22: =SUM(C22:N22) -> 80730 | C22: =C16*Planes!$D$6 -> 0 | D22: =D16*Planes!$D$6 -> 0 | E22: =E16*Planes!$D$6 -> 0 | F22: =F16*Planes!$D$6 -> 2990 | G22: =G16*Planes!$D$6 -> 2990 | H22: =H16*Planes!$D$6 -> 5980 | I22: =I16*Planes!$D$6 -> 5980 | J22: =J16*Planes!$D$6 -> 8970 | ... N22: =N16*Planes!$D$6 -> 17940
A23: Cobros de instalación | B23: =SUM(C23:N23) -> 0 | C23: =(C8+C9+C10)*CobroInstalacion -> 0 | D23: =(D8+D9+D10)*CobroInstalacion -> 0 | E23: =(E8+E9+E10)*CobroInstalacion -> 0 | F23: =(F8+F9+F10)*CobroInstalacion -> 0 | G23: =(G8+G9+G10)*CobroInstalacion -> 0 | H23: =(H8+H9+H10)*CobroInstalacion -> 0 | I23: =(I8+I9+I10)*CobroInstalacion -> 0 | J23: =(J8+J9+J10)*CobroInstalacion -> 0 | ... N23: =(N8+N9+N10)*CobroInstalacion -> 0
A24: Total cobrado | B24: =SUM(C24:N24) -> 317905 | C24: =SUM(C20:C23) -> 1985 | D24: =SUM(D20:D23) -> 3970 | E24: =SUM(E20:E23) -> 6450 | F24: =SUM(F20:F23) -> 11920 | G24: =SUM(G20:G23) -> 15395 | H24: =SUM(H20:H23) -> 22355 | I24: =SUM(I20:I23) -> 26820 | J24: =SUM(J20:J23) -> 33780 | ... N24: =SUM(N20:N23) -> 61605
A25: − ITBIS (es del fisco, no tuyo) | B25: =SUM(C25:N25) -> 48493.983 | C25: =C24-C24/(1+ITBIS*IncluyeITBIS) -> 302.79661 | D25: =D24-D24/(1+ITBIS*IncluyeITBIS) -> 605.59322 | E25: =E24-E24/(1+ITBIS*IncluyeITBIS) -> 983.89831 | F25: =F24-F24/(1+ITBIS*IncluyeITBIS) -> 1818.3051 | G25: =G24-G24/(1+ITBIS*IncluyeITBIS) -> 2348.3898 | H25: =H24-H24/(1+ITBIS*IncluyeITBIS) -> 3410.0847 | I25: =I24-I24/(1+ITBIS*IncluyeITBIS) -> 4091.1864 | J25: =J24-J24/(1+ITBIS*IncluyeITBIS) -> 5152.8814 | ... N25: =N24-N24/(1+ITBIS*IncluyeITBIS) -> 9397.3729
A26: − Comisión del cobro (tarjeta, pasarela) | B26: =SUM(C26:N26) -> 10776.441 | C26: =(C24-C25)*ComisionCobro -> 67.288136 | D26: =(D24-D25)*ComisionCobro -> 134.57627 | E26: =(E24-E25)*ComisionCobro -> 218.64407 | F26: =(F24-F25)*ComisionCobro -> 404.0678 | G26: =(G24-G25)*ComisionCobro -> 521.86441 | H26: =(H24-H25)*ComisionCobro -> 757.79661 | I26: =(I24-I25)*ComisionCobro -> 909.15254 | J26: =(J24-J25)*ComisionCobro -> 1145.0847 | ... N26: =(N24-N25)*ComisionCobro -> 2088.3051
A27: INGRESO NETO (lo que de verdad es tuyo) | B27: =SUM(C27:N27) -> 258634.58 | C27: =C24-C25-C26 -> 1614.9153 | D27: =D24-D25-D26 -> 3229.8305 | E27: =E24-E25-E26 -> 5247.4576 | F27: =F24-F25-F26 -> 9697.6271 | G27: =G24-G25-G26 -> 12524.746 | H27: =H24-H25-H26 -> 18187.119 | I27: =I24-I25-I26 -> 21819.661 | J27: =J24-J25-J26 -> 27482.034 | ... N27: =N24-N25-N26 -> 50119.322
A29: Lo que cuesta atender a los salones (sube con cada salón)
A30: IA, WhatsApp, notas de voz y voz · Esencial | B30: =SUM(C30:N30) -> 8594.4645 | C30: =C14*Planes!$B$27 -> 61.83068 | D30: =D14*Planes!$B$27 -> 123.66136 | E30: =E14*Planes!$B$27 -> 247.32272 | F30: =F14*Planes!$B$27 -> 370.98408 | G30: =G14*Planes!$B$27 -> 432.81476 | H30: =H14*Planes!$B$27 -> 556.47612 | I30: =I14*Planes!$B$27 -> 741.96816 | J30: =J14*Planes!$B$27 -> 865.62952 | ... N30: =N14*Planes!$B$27 -> 1545.767
A31: IA, WhatsApp, notas de voz y voz · Salón | B31: =SUM(C31:N31) -> 22457.786 | C31: =C15*Planes!$C$27 -> 198.74147 | D31: =D15*Planes!$C$27 -> 397.48294 | E31: =E15*Planes!$C$27 -> 596.22442 | F31: =F15*Planes!$C$27 -> 794.96589 | G31: =G15*Planes!$C$27 -> 1192.4488 | H31: =H15*Planes!$C$27 -> 1589.9318 | I31: =I15*Planes!$C$27 -> 1987.4147 | J31: =J15*Planes!$C$27 -> 2384.8977 | ... N31: =N15*Planes!$C$27 -> 4173.5709
A32: IA, WhatsApp, notas de voz y voz · Lounge | B32: =SUM(C32:N32) -> 17203.809 | C32: =C16*Planes!$D$27 -> 0 | D32: =D16*Planes!$D$27 -> 0 | E32: =E16*Planes!$D$27 -> 0 | F32: =F16*Planes!$D$27 -> 637.17812 | G32: =G16*Planes!$D$27 -> 637.17812 | H32: =H16*Planes!$D$27 -> 1274.3562 | I32: =I16*Planes!$D$27 -> 1274.3562 | J32: =J16*Planes!$D$27 -> 1911.5344 | ... N32: =N16*Planes!$D$27 -> 3823.0687
A33: Total atender salones | B33: =SUM(C33:N33) -> 48256.06 | C33: =SUM(C30:C32) -> 260.57215 | D33: =SUM(D30:D32) -> 521.1443 | E33: =SUM(E30:E32) -> 843.54714 | F33: =SUM(F30:F32) -> 1803.1281 | G33: =SUM(G30:G32) -> 2262.4417 | H33: =SUM(H30:H32) -> 3420.7641 | I33: =SUM(I30:I32) -> 4003.7391 | J33: =SUM(J30:J32) -> 5162.0615 | ... N33: =SUM(N30:N32) -> 9542.4066
A35: Sistema (se paga en dólares; aquí ya en pesos con el colchón)
A36: Servidores: app, base de datos y n8n | B36: =SUM(C36:N36) -> 30824.997 | C36: =(FijoServidor+FijoN8n)*FactorCambio -> 2568.7498 | D36: =(FijoServidor+FijoN8n)*FactorCambio -> 2568.7498 | E36: =(FijoServidor+FijoN8n)*FactorCambio -> 2568.7498 | F36: =(FijoServidor+FijoN8n)*FactorCambio -> 2568.7498 | G36: =(FijoServidor+FijoN8n)*FactorCambio -> 2568.7498 | H36: =(FijoServidor+FijoN8n)*FactorCambio -> 2568.7498 | I36: =(FijoServidor+FijoN8n)*FactorCambio -> 2568.7498 | J36: =(FijoServidor+FijoN8n)*FactorCambio -> 2568.7498 | ... N36: =(FijoServidor+FijoN8n)*FactorCambio -> 2568.7498
A37: Suscripción de voz (ElevenLabs) | B37: =SUM(C37:N37) -> 12715.311 | C37: =IF(C16>0,FijoVoz,0)*FactorCambio -> 0 | D37: =IF(D16>0,FijoVoz,0)*FactorCambio -> 0 | E37: =IF(E16>0,FijoVoz,0)*FactorCambio -> 0 | F37: =IF(F16>0,FijoVoz,0)*FactorCambio -> 1412.8124 | G37: =IF(G16>0,FijoVoz,0)*FactorCambio -> 1412.8124 | H37: =IF(H16>0,FijoVoz,0)*FactorCambio -> 1412.8124 | I37: =IF(I16>0,FijoVoz,0)*FactorCambio -> 1412.8124 | J37: =IF(J16>0,FijoVoz,0)*FactorCambio -> 1412.8124 | ... N37: =IF(N16>0,FijoVoz,0)*FactorCambio -> 1412.8124
A38: Dominio, correo, respaldos | B38: =SUM(C38:N38) -> 7706.2493 | C38: =FijoOtros*FactorCambio -> 642.18744 | D38: =FijoOtros*FactorCambio -> 642.18744 | E38: =FijoOtros*FactorCambio -> 642.18744 | F38: =FijoOtros*FactorCambio -> 642.18744 | G38: =FijoOtros*FactorCambio -> 642.18744 | H38: =FijoOtros*FactorCambio -> 642.18744 | I38: =FijoOtros*FactorCambio -> 642.18744 | J38: =FijoOtros*FactorCambio -> 642.18744 | ... N38: =FijoOtros*FactorCambio -> 642.18744
A39: API de YouTube (música del Lounge) | B39: =SUM(C39:N39) -> 0 | C39: =CostoYouTube*FactorCambio -> 0 | D39: =CostoYouTube*FactorCambio -> 0 | E39: =CostoYouTube*FactorCambio -> 0 | F39: =CostoYouTube*FactorCambio -> 0 | G39: =CostoYouTube*FactorCambio -> 0 | H39: =CostoYouTube*FactorCambio -> 0 | I39: =CostoYouTube*FactorCambio -> 0 | J39: =CostoYouTube*FactorCambio -> 0 | ... N39: =CostoYouTube*FactorCambio -> 0
A40: Total sistema | B40: =SUM(C40:N40) -> 51246.558 | C40: =SUM(C36:C39) -> 3210.9372 | D40: =SUM(D36:D39) -> 3210.9372 | E40: =SUM(E36:E39) -> 3210.9372 | F40: =SUM(F36:F39) -> 4623.7496 | G40: =SUM(G36:G39) -> 4623.7496 | H40: =SUM(H36:H39) -> 4623.7496 | I40: =SUM(I36:I39) -> 4623.7496 | J40: =SUM(J36:J39) -> 4623.7496 | ... N40: =SUM(N36:N39) -> 4623.7496
A42: Gastos de la empresa (se encienden o apagan en Supuestos)
A43: Tu sueldo | B43: =SUM(C43:N43) -> 0 | C43: =IF(C$5>=TuSueldoDesdeMes,TuSueldo,0)*IncluirSueldo -> 0 | D43: =IF(D$5>=TuSueldoDesdeMes,TuSueldo,0)*IncluirSueldo -> 0 | E43: =IF(E$5>=TuSueldoDesdeMes,TuSueldo,0)*IncluirSueldo -> 0 | F43: =IF(F$5>=TuSueldoDesdeMes,TuSueldo,0)*IncluirSueldo -> 0 | G43: =IF(G$5>=TuSueldoDesdeMes,TuSueldo,0)*IncluirSueldo -> 0 | H43: =IF(H$5>=TuSueldoDesdeMes,TuSueldo,0)*IncluirSueldo -> 0 | I43: =IF(I$5>=TuSueldoDesdeMes,TuSueldo,0)*IncluirSueldo -> 0 | J43: =IF(J$5>=TuSueldoDesdeMes,TuSueldo,0)*IncluirSueldo -> 0 | ... N43: =IF(N$5>=TuSueldoDesdeMes,TuSueldo,0)*IncluirSueldo -> 0
A44: Asistente (configura salones y atiende a las dueñas) | B44: =SUM(C44:N44) -> 0 | C44: =IF(C17>=AsistenteDesdeSalones,SueldoAsistente,0)*IncluirAsistente -> 0 | D44: =IF(D17>=AsistenteDesdeSalones,SueldoAsistente,0)*IncluirAsistente -> 0 | E44: =IF(E17>=AsistenteDesdeSalones,SueldoAsistente,0)*IncluirAsistente -> 0 | F44: =IF(F17>=AsistenteDesdeSalones,SueldoAsistente,0)*IncluirAsistente -> 0 | G44: =IF(G17>=AsistenteDesdeSalones,SueldoAsistente,0)*IncluirAsistente -> 0 | H44: =IF(H17>=AsistenteDesdeSalones,SueldoAsistente,0)*IncluirAsistente -> 0 | I44: =IF(I17>=AsistenteDesdeSalones,SueldoAsistente,0)*IncluirAsistente -> 0 | J44: =IF(J17>=AsistenteDesdeSalones,SueldoAsistente,0)*IncluirAsistente -> 0 | ... N44: =IF(N17>=AsistenteDesdeSalones,SueldoAsistente,0)*IncluirAsistente -> 0
A45: Cargas sociales (TSS + INFOTEP) | B45: =SUM(C45:N45) -> 0 | C45: =(C43+C44)*CargasSociales*IncluirCargas -> 0 | D45: =(D43+D44)*CargasSociales*IncluirCargas -> 0 | E45: =(E43+E44)*CargasSociales*IncluirCargas -> 0 | F45: =(F43+F44)*CargasSociales*IncluirCargas -> 0 | G45: =(G43+G44)*CargasSociales*IncluirCargas -> 0 | H45: =(H43+H44)*CargasSociales*IncluirCargas -> 0 | I45: =(I43+I44)*CargasSociales*IncluirCargas -> 0 | J45: =(J43+J44)*CargasSociales*IncluirCargas -> 0 | ... N45: =(N43+N44)*CargasSociales*IncluirCargas -> 0
A46: Publicidad | B46: =SUM(C46:N46) -> 36000 | C46: =PublicidadMensual*IncluirPublicidad -> 3000 | D46: =PublicidadMensual*IncluirPublicidad -> 3000 | E46: =PublicidadMensual*IncluirPublicidad -> 3000 | F46: =PublicidadMensual*IncluirPublicidad -> 3000 | G46: =PublicidadMensual*IncluirPublicidad -> 3000 | H46: =PublicidadMensual*IncluirPublicidad -> 3000 | I46: =PublicidadMensual*IncluirPublicidad -> 3000 | J46: =PublicidadMensual*IncluirPublicidad -> 3000 | ... N46: =PublicidadMensual*IncluirPublicidad -> 3000
...

Sheet Planes
A1: Lalan AI · Planes: costo, precio y margen por salón al mes
A2: Azul con fondo amarillo = lo negocias tú. Negro = se calcula. Todo en pesos salvo donde dice US$.
A4: Concepto | B4: Esencial | C4: Salón | D4: Lounge | E4: Nota
A5: Lo que negocias
A6: Precio mensual al salón | B6: 495 | C6: 1490 | D6: 2990 | E6: Lo que paga la dueña. Si IncluyeITBIS = 1, este precio ya lleva el ITBIS dentro.
A7: Mensajes de clientas incluidos al mes | B7: 400 | C7: 1500 | D7: 3000 | E7: Mensajes que Lalan atiende. Pasado el límite: paquete extra o sube de plan.
A8: Uso esperado del límite | B8: 0.7 | C8: 0.6 | D8: 0.6 | E8: Casi nadie usa el 100 %. Para el peor caso, pon 100 %.
A9: Mensajes que el equipo escribe desde la app al mes | B9: 40 | C9: 200 | D9: 500 | E9: También salen por la API de WhatsApp y cuentan para las 1.000 gratis.
A10: Respuestas de Lalan con la voz de la dueña | B10: 0 | C10: 0 | D10: 0.2 | E10: Parte de las respuestas que se mandan como audio. Solo en el plan Lounge.
A11: Avisos a la dueña al mes (plantilla) | B11: 10 | C11: 20 | D11: 40 | E11: Chats que pasan a una persona + citas sin especialista.
A12: Horas de soporte al mes | B12: 0.1 | C12: 0.5 | D12: 1 | E12: Tu tiempo atendiendo dudas y cambios. Solo cuenta para el margen de ESTA hoja; en Mi empresa el soporte lo pagan los sueldos.
A13: Búsquedas de música en YouTube al día | B13: 0 | C13: 5 | D13: 15 | E13: Gustos nuevos + canciones que las clientas buscan en el QR. El Esencial no tiene Lounge. Cada una gasta 100 unidades de la cuota diaria.
A14: ¿Meta se lo cobra al salón directamente? (1 = sí, 0 = lo pagas tú) | B14: 1 | C14: 1 | D14: 1 | E14: Recomendado 1: cada salón conecta su número y pone SU tarjeta en Meta. Así el costo de WhatsApp nunca es tuyo.
A15: Costos del mes (US$)
A16: Mensajes de clientas atendidos | B16: =B7*B8 -> 280 | C16: =C7*C8 -> 900 | D16: =D7*D8 -> 1800
A17: Inteligencia artificial | B17: =B16*CostoIAPorMensaje -> 0.9110136 | C17: =C16*CostoIAPorMensaje -> 2.928258 | D17: =D16*CostoIAPorMensaje -> 5.856516
A18: Transcripción de notas de voz | B18: =B16*CostoTranscripcionPorMensaje -> 0.0518 | C18: =C16*CostoTranscripcionPorMensaje -> 0.1665 | D18: =D16*CostoTranscripcionPorMensaje -> 0.333
A19: Mensajes que salen por WhatsApp (cantidad) | B19: =B16*RespuestasPorMensaje+B9 -> 308.8 | C19: =C16*RespuestasPorMensaje+C9 -> 1064 | D19: =D16*RespuestasPorMensaje+D9 -> 2228
A20: WhatsApp: respuestas pasadas las 1.000 gratis | B20: =MAX(0,B19-GratisPorNumero)*TarifaServicio*(1-B14) -> 0 | C20: =MAX(0,C19-GratisPorNumero)*TarifaServicio*(1-C14) -> 0 | D20: =MAX(0,D19-GratisPorNumero)*TarifaServicio*(1-D14) -> 0 | E20: 0 si Meta se lo cobra al salón.
A21: WhatsApp: avisos a la dueña | B21: =B11*TarifaUtilidad*(1-B14) -> 0 | C21: =C11*TarifaUtilidad*(1-C14) -> 0 | D21: =D11*TarifaUtilidad*(1-D14) -> 0
A22: Voz de la dueña | B22: =B16*RespuestasPorMensaje*B10*CostoVozPorRespuesta -> 0 | C22: =C16*RespuestasPorMensaje*C10*CostoVozPorRespuesta -> 0 | D22: =D16*RespuestasPorMensaje*D10*CostoVozPorRespuesta -> 3.73248
A23: Costo variable | B23: =B17+B18+B20+B21+B22 -> 0.9628136 | C23: =C17+C18+C20+C21+C22 -> 3.094758 | D23: =D17+D18+D20+D21+D22 -> 9.921996
A24: Parte de los costos fijos del sistema | B24: =FijoPorSalon -> 1.3846154 | C24: =FijoPorSalon -> 1.3846154 | D24: =FijoPorSalon -> 1.3846154 | E24: Fijos del sistema ÷ salones pagando. Los gastos de la empresa (sueldos, publicidad…) están en Mi empresa, no aquí.
A25: Costo total en dólares | B25: =B23+B24 -> 2.347429 | C25: =C23+C24 -> 4.4793734 | D25: =D23+D24 -> 11.306611
A26: Resultado del mes (RD$)
A27: Costo de atender este salón (lo que sube con cada salón) | B27: =B23*FactorCambio -> 61.83068 | C27: =C23*FactorCambio -> 198.74147 | D27: =D23*FactorCambio -> 637.17812 | E27: IA, notas de voz, WhatsApp y voz, en pesos. Es lo que usa Mi empresa por cada salón activo.
A28: Costos en dólares, pasados a pesos (con colchón) | B28: =B25*FactorCambio -> 150.74894 | C28: =C25*FactorCambio -> 287.65973 | D28: =D25*FactorCambio -> 726.09638
A29: Soporte | B29: =B12*CostoHoraSoporte -> 40 | C29: =C12*CostoHoraSoporte -> 200 | D29: =D12*CostoHoraSoporte -> 400
A30: COSTO TOTAL | B30: =B28+B29 -> 190.74894 | C30: =C28+C29 -> 487.65973 | D30: =D28+D29 -> 1126.0964
A31: Ingreso neto (sin ITBIS ni comisión) | B31: =B6*FactorNeto -> 402.71186 | C31: =C6*FactorNeto -> 1212.2034 | D31: =D6*FactorNeto -> 2432.5424
A32: GANANCIA | B32: =B31-B30 -> 211.96292 | C32: =C31-C30 -> 724.54366 | D32: =D31-D30 -> 1306.446
A33: Margen sobre el ingreso neto | B33: =IF(B31>0,B32/B31,0) -> 0.52633891 | C33: =IF(C31>0,C32/C31,0) -> 0.59770799 | D33: =IF(D31>0,D32/D31,0) -> 0.53707019
A34: Precio mínimo sugerido (para el margen objetivo) | B34: =IF((1-MargenObjetivo)*FactorNeto>0,B30/((1-MargenObjetivo)*FactorNeto),0) -> 390.7704 | C34: =IF((1-MargenObjetivo)*FactorNeto>0,C30/((1-MargenObjetivo)*FactorNeto),0) -> 999.02515 | D34: =IF((1-MargenObjetivo)*FactorNeto>0,D30/((1-MargenObjetivo)*FactorNeto),0) -> 2306.9336 | E34: Lo menos que deberías cobrar para ganar el margen objetivo, con estos supuestos.
A35: Costo por mensaje de clienta atendido | B35: =IF(B16>0,B30/B16,0) -> 0.68124622 | C35: =IF(C16>0,C30/C16,0) -> 0.54184415 | D35: =IF(D16>0,D30/D16,0) -> 0.6256091
A36: Lo que aporta cada salón para pagar los fijos | B36: =B31-(B23*FactorCambio+B29) -> 300.88118 | C36: =C31-(C23*FactorCambio+C29) -> 813.46192 | D36: =D31-(D23*FactorCambio+D29) -> 1395.3643 | E36: Ingreso neto menos lo variable y el soporte.
A37: Salones de este plan para cubrir los fijos | B37: =IF(B36>0,FijosTotal*FactorCambio/B36,"no cubre") -> 15.36736 | C37: =IF(C36>0,FijosTotal*FactorCambio/C36,"no cubre") -> 5.6840394 | D37: =IF(D36>0,FijosTotal*FactorCambio/D36,"no cubre") -> 3.3136506 | E37: Si solo vendieras este plan: cuántos salones necesitas para no perder.
A38: Paquete extra de mensajes
A39: Mensajes del paquete extra | B39: 250 | C39: 500 | D39: 1000
A40: Costo del paquete | B40: =B39*(CostoIAPorMensaje+CostoTranscripcionPorMensaje)*FactorCambio -> 55.205964 | C40: =C39*(CostoIAPorMensaje+CostoTranscripcionPorMensaje)*FactorCambio -> 110.41193 | D40: =D39*(CostoIAPorMensaje+CostoTranscripcionPorMensaje)*FactorCambio -> 220.82386
A41: Precio sugerido del paquete (margen objetivo) | B41: =IF((1-MargenObjetivo)*FactorNeto>0,CEILING(B40/((1-MargenObjetivo)*FactorNeto),5),0) -> 115 | C41: =IF((1-MargenObjetivo)*FactorNeto>0,CEILING(C40/((1-MargenObjetivo)*FactorNeto),5),0) -> 230 | D41: =IF((1-MargenObjetivo)*FactorNeto>0,CEILING(D40/((1-MargenObjetivo)*FactorNeto),5),0) -> 455 | E41: Redondeado a 5 pesos.

Sheet Supuestos
A1: Lalan AI · Supuestos del modelo de costos
A2: Cambia solo las celdas en AZUL con fondo amarillo. Todo lo demás se calcula solo. Precios de proveedores verificados el 26 de septiembre de 2026 (ver hoja Fuentes).
A4: Moneda, impuestos y cobro
A5: Supuesto | B5: Valor | C5: Unidad | D5: De dónde sale / nota
A6: Tasa del dólar (venta) | B6: 59.4618 | C6: RD$ por US$ | D6: Banco Central RD, tasa de venta del 24-sep-2026 (vigente hasta el 25-sep). Actualízala al negociar.
A7: Colchón cambiario | B7: 0.08 | C7: % | D7: Protección por si el peso se deprecia mientras el precio en pesos queda fijo. Todos los costos en dólares se multiplican por (1 + colchón).
A8: ITBIS | B8: 0.18 | C8: % | D8: Impuesto a la venta en RD.
A9: ¿El precio del plan ya incluye ITBIS? (1 = sí, 0 = no) | B9: 1 | C9: 1 / 0 | D9: Con 1, de cada RD$ 118 cobrados, RD$ 18 son del fisco. Pon 0 si facturas ITBIS aparte o si no estás obligado (consúltalo con tu contador).
A10: Comisión del cobro (tarjeta, pasarela o transferencia) | B10: 0.04 | C10: % del precio | D10: Estimado. Ajusta a tu medio de cobro real (Azul, CardNet, PayPal, Stripe…). Transferencia bancaria ≈ 0 %.
A11: Margen que quieres ganar sobre el ingreso neto | B11: 0.4 | C11: % | D11: Se usa para calcular el precio mínimo sugerido de cada plan.
A12: Inteligencia artificial (OpenRouter · gpt-4.1-mini)
A13: Supuesto | B13: Valor | C13: Unidad | D13: De dónde sale / nota
A14: Precio de entrada | B14: 0.4 | C14: US$ / millón de tokens | D14: OpenRouter, openai/gpt-4.1-mini: US$ 0.40 entrada · US$ 1.60 salida por millón.
A15: Precio de salida | B15: 1.6 | C15: US$ / millón de tokens | D15: Ídem.
A16: Precio de entrada en caché | B16: 0.1 | C16: US$ / millón de tokens | D16: ESTIMADO: OpenAI cobra ~25 % del precio por la parte del prompt que se repite (caché). Verifica en OpenRouter.
A17: Tokens de entrada por llamada al modelo | B17: 6500 | C17: tokens | D17: Medido el 26-sep-2026 con el prompt nuevo, en un salón de 22 servicios y 6 especialistas: mensaje de sistema 3.800 (3.150 fijos + 650 que cambian) + 12 herramientas 1.400 + mensaje y resultados de herramientas ~1.300. Con unos 50 servicios, súmale ~800. Compáralo con la columna Tokens de la actividad de OpenRouter.
A18: Tokens de salida por llamada | B18: 250 | C18: tokens | D18: Una respuesta de chat o una llamada a herramienta.
A19: Llamadas al modelo cada vez que Lalan contesta | B19: 2 | C19: llamadas | D19: Una pregunta simple = 1; agendar = 3 o 4 (consulta, agenda, respuesta). 2 es un promedio prudente.
A20: Parte de la entrada que va en caché | B20: 0.55 | C20: % | D20: ESTIMADO. Desde el 26-sep el prompt pone primero lo fijo (reglas, servicios, herramientas ≈ 78 % de la entrada) y al final lo que cambia. La 2.ª y 3.ª llamada de cada respuesta casi siempre sale de caché; la 1.ª, solo si ese salón tuvo otro mensaje en los últimos ~5-10 min. Salón con poco movimiento ≈ 40 %; salón con mucho ≈ 65 %. Verifícalo en OpenRouter (Activity → cached tokens).
A21: Mensajes de clientas que llegan en ráfaga y se contestan juntos | B21: 0.2 | C21: % | D21: ESTIMADO. "hola" · "quería una cita" · "para mañana" = 3 mensajes, 1 respuesta. Lalan espera 7 s por si la clienta sigue escribiendo (se cambia en el nodo Configuración Lalan de n8n). Cuéntalo tú: respuestas de Lalan ÷ mensajes de clientas en el panel de bots.
A22: Comisión de OpenRouter al recargar créditos | B22: 0.055 | C22: % | D22: ESTIMADO (~5,5 % por compra de créditos con tarjeta). Verifica en tu cuenta.
A23: → Costo de IA por mensaje de clienta | B23: =((TokensEntrada*(1-PorcCache)*PrecioEntrada+TokensEntrada*PorcCache*PrecioCache+TokensSalida*PrecioSalida)/1000000)*LlamadasPorMensaje*(1-PorcAgrupados)*(1+ComisionOpenRouter) -> 0.00325362 | C23: US$
A24: Notas de voz de las clientas (transcripción · Groq Whisper)
A25: Supuesto | B25: Valor | C25: Unidad | D25: De dónde sale / nota
A26: Precio de transcripción | B26: 0.111 | C26: US$ / hora de audio | D26: Groq, whisper-large-v3.
A27: Duración promedio de una nota de voz | B27: 20 | C27: segundos | D27: Supuesto.
A28: Mínimo facturable por audio | B28: 10 | C28: segundos | D28: Groq cobra al menos 10 s por audio.
A29: Mensajes de clientas que llegan como nota de voz | B29: 0.3 | C29: % | D29: Supuesto; en RD se usan mucho.
A30: → Costo de transcripción por mensaje de clienta (promedio) | B30: =PorcNotasVoz*MAX(SegundosNota,MinimoSegundos)/3600*PrecioTranscripcion -> 0.000185 | C30: US$
A31: WhatsApp (Meta) · desde el 1 de octubre de 2026
A32: Supuesto | B32: Valor | C32: Unidad | D32: De dónde sale / nota
A33: Tarifa por mensaje de servicio (respuestas) pasado el gratis | B33: 0.0113 | C33: US$ / mensaje | D33: Resto de América Latina (RD está en este grupo). Desde el 1-oct-2026 Meta cobra las respuestas de servicio pasadas las 1.000 gratis por número al mes.
A34: Mensajes de servicio gratis por número al mes | B34: 1000 | C34: mensajes | D34: Por NÚMERO de WhatsApp (cada salón tiene el suyo). No se acumulan.
A35: Tarifa de plantilla de utilidad (aviso a la dueña) | B35: 0.0113 | C35: US$ / mensaje | D35: Misma tarifa. Gratis si la dueña escribió a ese número en las últimas 24 h; aquí se asume que siempre se paga.
A36: Mensajes que manda Lalan cada vez que contesta | B36: 1.2 | C36: mensajes | D36: A veces responde en dos mensajes (la cita y luego el Lounge).
A37: → Mensajes que salen por cada mensaje de una clienta | B37: =MensajesPorRespuesta*(1-PorcAgrupados) -> 0.96 | C37: mensajes | D37: Los mensajes en ráfaga se contestan juntos: una sola respuesta.
A38: Voz de la dueña (ElevenLabs · clonación de voz)
A39: Supuesto | B39: Valor | C39: Unidad | D39: De dónde sale / nota
A40: Precio por cada 1.000 caracteres convertidos a voz | B40: 0.06 | C40: US$ | D40: ElevenLabs API, modelos Flash/Turbo: US$ 0.06 por 1.000 caracteres. Multilingual (mejor calidad): US$ 0.12.
A41: Caracteres por respuesta hablada | B41: 180 | C41: caracteres | D41: Una respuesta de chat típica (~30 palabras).
...

Sheet Negociación
A1: Simulador para negociar con un salón
A2: Elige el plan de base y cambia lo que estés negociando. Lo demás sale de la hoja Planes y Supuestos.
A4: Lo que negocias
A5: Plan de base (1 = Esencial, 2 = Salón, 3 = Lounge) | B5: 2
A6: Plan elegido | B6: =INDEX(Planes!$B$4:$D$4,1,B5) -> Salón
A7: Precio de lista | B7: =INDEX(Planes!$B$6:$D$6,1,B5) -> 1490
A8: Descuento que ofreces | B8: 0.1 | C8: Ej.: 10 % por pago anual o por ser de las primeras.
A9: Precio negociado | B9: =B7*(1-B8) -> 1341
A10: Mensajes incluidos | B10: =INDEX(Planes!$B$7:$D$7,1,B5) -> 1500 | C10: Para cambiarlo, escribe encima un número.
A11: Uso esperado | B11: =INDEX(Planes!$B$8:$D$8,1,B5) -> 0.6
A12: Mensajes del equipo desde la app | B12: =INDEX(Planes!$B$9:$D$9,1,B5) -> 200
A13: Respuestas con la voz de la dueña | B13: =INDEX(Planes!$B$10:$D$10,1,B5) -> 0
A14: Avisos a la dueña | B14: =INDEX(Planes!$B$11:$D$11,1,B5) -> 20
A15: Horas de soporte | B15: =INDEX(Planes!$B$12:$D$12,1,B5) -> 0.5
A16: ¿Meta se lo cobra al salón? (1/0) | B16: =INDEX(Planes!$B$14:$D$14,1,B5) -> 1
A17: Resultado
A18: Mensajes atendidos | B18: =B10*B11 -> 900
A19: Mensajes que salen por WhatsApp | B19: =B18*RespuestasPorMensaje+B12 -> 1064
A20: Costo variable (US$) | B20: =B18*(CostoIAPorMensaje+CostoTranscripcionPorMensaje)+MAX(0,B19-GratisPorNumero)*TarifaServicio*(1-B16)+B14*TarifaUtilidad*(1-B16)+B18*RespuestasPorMensaje*B13*CostoVozPorRespuesta -> 3.094758
A21: Costo total del mes | B21: =(B20+FijoPorSalon)*FactorCambio+B15*CostoHoraSoporte -> 487.65973
A22: Ingreso neto | B22: =B9*FactorNeto -> 1090.9831
A23: GANANCIA DEL MES | B23: =B22-B21 -> 603.32332
A24: Margen | B24: =IF(B22>0,B23/B22,0) -> 0.55300888
A25: Ganancia en un año con este salón | B25: =B23*12 -> 7239.8798
A26: ¿Conviene? | B26: =IF(B24>=MargenObjetivo,"Sí: cumple el margen objetivo",IF(B23>0,"Deja ganancia, pero bajo el objetivo","No: pierdes dinero")) -> Sí: cumple el margen objetivo

Sheet Sensibilidad
A1: ¿Qué pasa con el margen si algo cambia?
A2: Margen de cada plan (hoja Planes) si el dólar sube, si la IA cuesta más, o si la caché no rinde lo esperado. Escribe tus propios factores en las celdas azules.
A4: Escenario | B4: Factor dólar | C4: Factor IA | D4: Esencial | E4: Salón | F4: Lounge
A5: Hoy (supuestos tal cual) | B5: 1 | C5: 1 | D5: =IF(Planes!B31>0,(Planes!B31-((Planes!B17*$C5+(Planes!B23-Planes!B17+Planes!B24))*FactorCambio*$B5+Planes!B29))/Planes!B31,0) -> 0.52633891 | E5: =IF(Planes!C31>0,(Planes!C31-((Planes!C17*$C5+(Planes!C23-Planes!C17+Planes!C24))*FactorCambio*$B5+Planes!C29))/Planes!C31,0) -> 0.59770799 | F5: =IF(Planes!D31>0,(Planes!D31-((Planes!D17*$C5+(Planes!D23-Planes!D17+Planes!D24))*FactorCambio*$B5+Planes!D29))/Planes!D31,0) -> 0.53707019
A6: El dólar sube 10 % | B6: 1.1 | C6: 1 | D6: =IF(Planes!B31>0,(Planes!B31-((Planes!B17*$C6+(Planes!B23-Planes!B17+Planes!B24))*FactorCambio*$B6+Planes!B29))/Planes!B31,0) -> 0.48890546 | E6: =IF(Planes!C31>0,(Planes!C31-((Planes!C17*$C6+(Planes!C23-Planes!C17+Planes!C24))*FactorCambio*$B6+Planes!C29))/Planes!C31,0) -> 0.57397768 | F6: =IF(Planes!D31>0,(Planes!D31-((Planes!D17*$C6+(Planes!D23-Planes!D17+Planes!D24))*FactorCambio*$B6+Planes!D29))/Planes!D31,0) -> 0.50722091
A7: El dólar sube 20 % | B7: 1.2 | C7: 1 | D7: =IF(Planes!B31>0,(Planes!B31-((Planes!B17*$C7+(Planes!B23-Planes!B17+Planes!B24))*FactorCambio*$B7+Planes!B29))/Planes!B31,0) -> 0.45147201 | E7: =IF(Planes!C31>0,(Planes!C31-((Planes!C17*$C7+(Planes!C23-Planes!C17+Planes!C24))*FactorCambio*$B7+Planes!C29))/Planes!C31,0) -> 0.55024736 | F7: =IF(Planes!D31>0,(Planes!D31-((Planes!D17*$C7+(Planes!D23-Planes!D17+Planes!D24))*FactorCambio*$B7+Planes!D29))/Planes!D31,0) -> 0.47737163
A8: La IA cuesta el doble (otro modelo o más llamadas) | B8: 1 | C8: 2 | D8: =IF(Planes!B31>0,(Planes!B31-((Planes!B17*$C8+(Planes!B23-Planes!B17+Planes!B24))*FactorCambio*$B8+Planes!B29))/Planes!B31,0) -> 0.38106345 | E8: =IF(Planes!C31>0,(Planes!C31-((Planes!C17*$C8+(Planes!C23-Planes!C17+Planes!C24))*FactorCambio*$B8+Planes!C29))/Planes!C31,0) -> 0.44257804 | F8: =IF(Planes!D31>0,(Planes!D31-((Planes!D17*$C8+(Planes!D23-Planes!D17+Planes!D24))*FactorCambio*$B8+Planes!D29))/Planes!D31,0) -> 0.38245907
A9: La caché no rinde (IA ~1,55× más cara) | B9: 1 | C9: 1.55 | D9: =IF(Planes!B31>0,(Planes!B31-((Planes!B17*$C9+(Planes!B23-Planes!B17+Planes!B24))*FactorCambio*$B9+Planes!B29))/Planes!B31,0) -> 0.44643741 | E9: =IF(Planes!C31>0,(Planes!C31-((Planes!C17*$C9+(Planes!C23-Planes!C17+Planes!C24))*FactorCambio*$B9+Planes!C29))/Planes!C31,0) -> 0.51238652 | F9: =IF(Planes!D31>0,(Planes!D31-((Planes!D17*$C9+(Planes!D23-Planes!D17+Planes!D24))*FactorCambio*$B9+Planes!D29))/Planes!D31,0) -> 0.45203407
A10: Peor caso: dólar +20 % e IA ×2 | B10: 1.2 | C10: 2 | D10: =IF(Planes!B31>0,(Planes!B31-((Planes!B17*$C10+(Planes!B23-Planes!B17+Planes!B24))*FactorCambio*$B10+Planes!B29))/Planes!B31,0) -> 0.27714147 | E10: =IF(Planes!C31>0,(Planes!C31-((Planes!C17*$C10+(Planes!C23-Planes!C17+Planes!C24))*FactorCambio*$B10+Planes!C29))/Planes!C31,0) -> 0.36409142 | F10: =IF(Planes!D31>0,(Planes!D31-((Planes!D17*$C10+(Planes!D23-Planes!D17+Planes!D24))*FactorCambio*$B10+Planes!D29))/Planes!D31,0) -> 0.29183828

Sheet Qué incluye
A1: Qué incluye cada plan (propuesta)
A2: Borrador para el documento comercial. Cámbialo con libertad: los costos no dependen de este texto.
A4: Función | B4: Esencial | C4: Salón | D4: Lounge
A5: Para quién | B5: Uñas y locales pequeños | C5: Salones con equipo | D5: Salones premium y spas
A6: Precio mensual | B6: =Planes!B6 -> 495 | C6: =Planes!C6 -> 1490 | D6: =Planes!D6 -> 2990
A7: Mensajes de clientas al mes | B7: =Planes!B7 -> 400 | C7: =Planes!C7 -> 1500 | D7: =Planes!D7 -> 3000
A8: Lalan responde en WhatsApp 24/7 | B8: Sí | C8: Sí | D8: Sí
A9: Entiende notas de voz | B9: Sí | C9: Sí | D9: Sí
A10: Agenda, reagenda y cancela sola | B10: Sí | C10: Sí | D10: Sí
A11: Aviso a la dueña por WhatsApp | B11: Sí | C11: Sí | D11: Sí
A12: Agenda y ficha de clientas | B12: Sí | C12: Sí | D12: Sí
A13: Especialistas y zonas | B13: Sí | C13: Sí | D13: Sí
A14: Lounge: música y gustos de cada clienta | B14: — | C14: Sí | D14: Sí
A15: Bienvenida con sus gustos al llegar | B15: — | C15: Sí | D15: Sí
A16: Caja y comandas | B16: — | C16: Sí | D16: Sí
A17: Informes (citas, ganancias, quién agendó) | B17: Completo | C17: Completo | D17: Completo
A18: Pantalla de turnos | B18: — | C18: Sí | D18: Sí
A19: Respuestas con la voz de la dueña | B19: — | C19: — | D19: Sí
... A23: Soporte | B23: Por WhatsApp | C23: Por WhatsApp | D23: Prioritario

Sheet Fuentes
A1: De dónde salen los precios (consultados el 26-sep-2026)
A3: Tasa del dólar (BCRD) | B3: https://acento.com.do/economia/precio-del-dolar-hoy-en-republica-dominicana-tasa-de-compra-y-venta-este-jueves-24-de-septiembre-de-2026-9758215.html
A4: gpt-4.1-mini en OpenRouter | B4: https://openrouter.ai/openai/gpt-4.1-mini
A5: Precios de WhatsApp (Meta) | B5: https://developers.facebook.com/documentation/business-messaging/whatsapp/pricing
A6: Cobro de mensajes de servicio desde 1-oct-2026 | B6: https://360dialog.com/blog/whatsapp-service-message-charging-october-2026/
A7: Groq Whisper large v3 | B7: https://console.groq.com/docs/model/whisper-large-v3
A8: ElevenLabs (planes y API) | B8: https://texttolab.com/blog/elevenlabs-pricing
A9: Railway (planes) | B9: https://docs.railway.com/pricing/plans
A10: YouTube Data API: cuota y costo por llamada | B10: https://developers.google.com/youtube/v3/determine_quota_cost
A11: YouTube Data API: pedir más cuota | B11: https://support.google.com/youtube/contact/yt_api_form
A12: Aportes TSS del empleador 2026 | B12: https://bolsillopractico.com/tramites/aportes-tss-empleador-porcentajes-rd/
A14: Estimados sin fuente directa
A15: Caché de OpenAI, comisión de OpenRouter, comisión de cobro, costos de servidor, uso por salón: marcados como ESTIMADO o Supuesto en la hoja Supuestos.
