Workbook
Name URL_BASE: 'Conexión'!$C$5
Name CLAVE_REPORTES: 'Conexión'!$C$6
Name DESDE: 'Conexión'!$C$7

Sheet Inicio
B1: Lalan · Piloto
B2: Lo que dicen las dueñas, sus equipos y sus clientas, al lado de lo que muestran los números de la plataforma.
B4: Cómo se usa
B5: 1. Conecta | C5: En la hoja Conexión pega la clave de reportes (se genera en Plataforma → Piloto) y dale Datos → Actualizar todo.
B6: 2. Elige salones | C6: En Perfil apunta cada salón candidato y puntúalo. Marca "Sí" en Seleccionado a los del piloto.
B7: 3. Día 0 | C7: Antes de instalar, llena la Línea base con la dueña (cómo trabaja hoy).
B8: 4. Cada semana | C8: 15 minutos con cada dueña: una fila en Revisión semanal. Los números de esa semana se llenan solos.
B9: 5. Encuestas | C9: Clientas y Equipo: pásalas por Google Forms o Microsoft Forms (las preguntas están en Formularios) y pega aquí las respuestas.
B10: 6. Cierre | C10: Al final del piloto: NPS, si seguiría, cuánto pagaría y su testimonio.
B11: 7. Análisis | C11: Cruza todo por salón. Actualiza los datos antes de mirarlo.
B13: Qué es cada color
B14: Lo llenas tú | C14: Celdas amarillas con letra azul.
B15: Se calcula solo | C15: Encabezados grises: fórmulas o datos de la plataforma. No hace falta tocarlos.
B16: Ejemplo | C16: La primera fila de cada cuestionario es un ejemplo en gris. No cuenta en el análisis; puedes dejarla.
B19: Privacidad
C20: La plataforma solo manda números por salón y por día. Ningún nombre de clienta, texto de chat ni monto de dinero sale de Lalan. Las respuestas de las encuestas viven solo en este archivo.
B22: Hojas
B23: Conexión | C23: Dirección, clave y desde qué fecha traer los datos.
B24: Perfil | C24: Salones candidatos, puntaje de selección y quién entra.
B25: Línea base | C25: Cómo trabajaba cada salón antes de Lalan (día 0).
B26: Revisión semanal | C26: Nota de 1 a 5 por módulo, horas ahorradas y comentarios, con los números de la semana.
B27: Clientas | C27: Respuestas de la encuesta a clientas.
B28: Equipo | C28: Respuestas de la encuesta al equipo del salón.
B29: Cierre | C29: Entrevista final: NPS, precio, testimonio.
B30: Análisis | C30: El cruce por salón y el resumen del piloto.
B31: Formularios | C31: Las preguntas listas para Google Forms o Microsoft Forms.
B32: Datos … | C32: Las tres tablas que baja Power Query. No escribas en ellas: se reemplazan al actualizar.

Sheet Conexión
B1: Conexión con la plataforma
B2: Excel de escritorio (Windows o Mac) con Power Query. Datos → Actualizar todo baja los números al día.
B5: Dirección de la API | C5: https://api.lalan.gomezsantana.com/api/v1 | D5: Ya viene escrita. Solo cámbiala si la API se muda.
B6: Clave de reportes | D6: Pégala aquí. Se genera en Plataforma → Piloto → Números del piloto en Excel. Empieza con lalan_rep_. Es de solo lectura; si se filtra, revócala y genera otra.
B7: Traer datos desde | D7: Opcional: una fecha (por ejemplo el día 0 del piloto). Vacío = los últimos 120 días.
B10: Primera vez
B11: 1. | C11: Pega la clave en la celda amarilla y ve a Datos → Actualizar todo.
B12: 2. | C12: Excel pregunta cómo entrar a la dirección web: elige Anónimo y dale Conectar.
B13: 3. | C13: Si pregunta por la privacidad de los datos, marca "Omitir comprobaciones de niveles de privacidad" (o pon las dos fuentes como Organizativo) y Guardar.
B14: 4. | C14: Listo: las hojas Datos salones, Datos diario y Datos pantallas se llenan, y con ellas la Revisión semanal y el Análisis.
B17: Si algo falla
B18: "La clave no sirve o fue revocada" | C18: Genera otra en Plataforma → Piloto y pégala en la celda amarilla.
B19: "Demasiadas actualizaciones seguidas" | C19: Espera un minuto y vuelve a actualizar.
B20: "Falta la clave de reportes" | C20: La celda de la clave está vacía.
B21: Pide usuario y contraseña | C21: Datos → Obtener datos → Configuración de origen de datos → elige la dirección → Editar permisos → Anónimo.
B22: Error de privacidad (Formula.Firewall) | C22: Datos → Obtener datos → Opciones de consulta → Libro actual → Privacidad → Omitir los niveles de privacidad.
B23: Mac | C23: Funciona igual con Excel 365 para Mac (Datos → Actualizar todo).

Sheet Perfil
A1: Perfil y selección de salones
A2: Una fila por salón candidato. Puntúa del 1 al 5; el puntaje (0 a 100) usa los pesos de la fila 3.
J3: Pesos → | K3: 3 | L3: 3 | M3: 2 | N3: 1 | O3: 2
A4: Salón | B4: ID en Lalan | C4: Dueña | D4: Ciudad | E4: Tipo | F4: Sedes | G4: Especialistas | H4: Citas por semana (aprox.) | I4: Mensajes de WhatsApp al día (aprox.) | J4: Cómo agenda hoy | K4: Volumen de chats (1-5) | L4: Dolor por responder (1-5) | M4: Ganas de probar y opinar (1-5) | N4: Facilidad con la tecnología (1-5) | O4: Tiempo para la revisión semanal (1-5) | P4: Puntaje (0-100) | Q4: Seleccionado | R4: Notas
A5: Salón Ejemplo | B5: =IF(A5="","",IFERROR(INDEX('Datos salones'!$A:$A,MATCH(A5,'Datos salones'!$B:$B,0)),"no está en Lalan")) | C5: Ana Pérez | D5: Santiago | E5: Uñas | F5: 1 | G5: 4 | H5: 60 | I5: 40 | J5: WhatsApp | K5: 4 | L5: 5 | M5: 4 | N5: 3 | O5: 4 | P5: =IF(COUNT(K5:O5)=0,"",ROUND(SUMPRODUCT(K5:O5,$K$3:$O$3)/SUMPRODUCT(--(K5:O5<>""),$K$3:$O$3)*20,0)) | Q5: Sí | R5: Tiene dos recepcionistas; contesta de noche
B6: =IF(A6="","",IFERROR(INDEX('Datos salones'!$A:$A,MATCH(A6,'Datos salones'!$B:$B,0)),"no está en Lalan")) | P6: =IF(COUNT(K6:O6)=0,"",ROUND(SUMPRODUCT(K6:O6,$K$3:$O$3)/SUMPRODUCT(--(K6:O6<>""),$K$3:$O$3)*20,0))
B7: =IF(A7="","",IFERROR(INDEX('Datos salones'!$A:$A,MATCH(A7,'Datos salones'!$B:$B,0)),"no está en Lalan")) | P7: =IF(COUNT(K7:O7)=0,"",ROUND(SUMPRODUCT(K7:O7,$K$3:$O$3)/SUMPRODUCT(--(K7:O7<>""),$K$3:$O$3)*20,0))
B8: =IF(A8="","",IFERROR(INDEX('Datos salones'!$A:$A,MATCH(A8,'Datos salones'!$B:$B,0)),"no está en Lalan")) | P8: =IF(COUNT(K8:O8)=0,"",ROUND(SUMPRODUCT(K8:O8,$K$3:$O$3)/SUMPRODUCT(--(K8:O8<>""),$K$3:$O$3)*20,0))
B9: =IF(A9="","",IFERROR(INDEX('Datos salones'!$A:$A,MATCH(A9,'Datos salones'!$B:$B,0)),"no está en Lalan")) | P9: =IF(COUNT(K9:O9)=0,"",ROUND(SUMPRODUCT(K9:O9,$K$3:$O$3)/SUMPRODUCT(--(K9:O9<>""),$K$3:$O$3)*20,0))
B10: =IF(A10="","",IFERROR(INDEX('Datos salones'!$A:$A,MATCH(A10,'Datos salones'!$B:$B,0)),"no está en Lalan")) | P10: =IF(COUNT(K10:O10)=0,"",ROUND(SUMPRODUCT(K10:O10,$K$3:$O$3)/SUMPRODUCT(--(K10:O10<>""),$K$3:$O$3)*20,0))
B11: =IF(A11="","",IFERROR(INDEX('Datos salones'!$A:$A,MATCH(A11,'Datos salones'!$B:$B,0)),"no está en Lalan")) | P11: =IF(COUNT(K11:O11)=0,"",ROUND(SUMPRODUCT(K11:O11,$K$3:$O$3)/SUMPRODUCT(--(K11:O11<>""),$K$3:$O$3)*20,0))
B12: =IF(A12="","",IFERROR(INDEX('Datos salones'!$A:$A,MATCH(A12,'Datos salones'!$B:$B,0)),"no está en Lalan")) | P12: =IF(COUNT(K12:O12)=0,"",ROUND(SUMPRODUCT(K12:O12,$K$3:$O$3)/SUMPRODUCT(--(K12:O12<>""),$K$3:$O$3)*20,0))
B13: =IF(A13="","",IFERROR(INDEX('Datos salones'!$A:$A,MATCH(A13,'Datos salones'!$B:$B,0)),"no está en Lalan")) | P13: =IF(COUNT(K13:O13)=0,"",ROUND(SUMPRODUCT(K13:O13,$K$3:$O$3)/SUMPRODUCT(--(K13:O13<>""),$K$3:$O$3)*20,0))
B14: =IF(A14="","",IFERROR(INDEX('Datos salones'!$A:$A,MATCH(A14,'Datos salones'!$B:$B,0)),"no está en Lalan")) | P14: =IF(COUNT(K14:O14)=0,"",ROUND(SUMPRODUCT(K14:O14,$K$3:$O$3)/SUMPRODUCT(--(K14:O14<>""),$K$3:$O$3)*20,0))
B15: =IF(A15="","",IFERROR(INDEX('Datos salones'!$A:$A,MATCH(A15,'Datos salones'!$B:$B,0)),"no está en Lalan")) | P15: =IF(COUNT(K15:O15)=0,"",ROUND(SUMPRODUCT(K15:O15,$K$3:$O$3)/SUMPRODUCT(--(K15:O15<>""),$K$3:$O$3)*20,0))
B16: =IF(A16="","",IFERROR(INDEX('Datos salones'!$A:$A,MATCH(A16,'Datos salones'!$B:$B,0)),"no está en Lalan")) | P16: =IF(COUNT(K16:O16)=0,"",ROUND(SUMPRODUCT(K16:O16,$K$3:$O$3)/SUMPRODUCT(--(K16:O16<>""),$K$3:$O$3)*20,0))
B17: =IF(A17="","",IFERROR(INDEX('Datos salones'!$A:$A,MATCH(A17,'Datos salones'!$B:$B,0)),"no está en Lalan")) | P17: =IF(COUNT(K17:O17)=0,"",ROUND(SUMPRODUCT(K17:O17,$K$3:$O$3)/SUMPRODUCT(--(K17:O17<>""),$K$3:$O$3)*20,0))

Sheet Línea base
A1: Línea base (día 0)
A2: Antes de instalar Lalan: cómo trabaja hoy cada salón. Es contra lo que se compara al final.
A4: Salón | B4: ID en Lalan | C4: Fecha | D4: Horas a la semana respondiendo WhatsApp | E4: Mensajes de clientas al día | F4: Minutos que tarda en responder (típico) | G4: Citas por semana | H4: Clientas que faltan por semana | I4: Clientas que se pierden por no contestar a tiempo (semana) | J4: Cómo agenda hoy | K4: Satisfacción con su forma actual (1-5) | L4: Lo que más tiempo le quita | M4: Qué espera de Lalan
A5: Salón Ejemplo | B5: =IF(A5="","",IFERROR(INDEX(Perfil!$B$6:$B$17,MATCH(A5,Perfil!$A$6:$A$17,0)),"")) | C5: 46296 | D5: 10 | E5: 40 | F5: 45 | G5: 60 | H5: 6 | I5: 3 | J5: WhatsApp | K5: 2 | L5: Contestar precios por WhatsApp | M5: Que conteste de noche y agende sola
B6: =IF(A6="","",IFERROR(INDEX(Perfil!$B$6:$B$17,MATCH(A6,Perfil!$A$6:$A$17,0)),""))
B7: =IF(A7="","",IFERROR(INDEX(Perfil!$B$6:$B$17,MATCH(A7,Perfil!$A$6:$A$17,0)),""))
B8: =IF(A8="","",IFERROR(INDEX(Perfil!$B$6:$B$17,MATCH(A8,Perfil!$A$6:$A$17,0)),""))
B9: =IF(A9="","",IFERROR(INDEX(Perfil!$B$6:$B$17,MATCH(A9,Perfil!$A$6:$A$17,0)),""))
B10: =IF(A10="","",IFERROR(INDEX(Perfil!$B$6:$B$17,MATCH(A10,Perfil!$A$6:$A$17,0)),""))
B11: =IF(A11="","",IFERROR(INDEX(Perfil!$B$6:$B$17,MATCH(A11,Perfil!$A$6:$A$17,0)),""))
B12: =IF(A12="","",IFERROR(INDEX(Perfil!$B$6:$B$17,MATCH(A12,Perfil!$A$6:$A$17,0)),""))
B13: =IF(A13="","",IFERROR(INDEX(Perfil!$B$6:$B$17,MATCH(A13,Perfil!$A$6:$A$17,0)),""))
B14: =IF(A14="","",IFERROR(INDEX(Perfil!$B$6:$B$17,MATCH(A14,Perfil!$A$6:$A$17,0)),""))
B15: =IF(A15="","",IFERROR(INDEX(Perfil!$B$6:$B$17,MATCH(A15,Perfil!$A$6:$A$17,0)),""))
B16: =IF(A16="","",IFERROR(INDEX(Perfil!$B$6:$B$17,MATCH(A16,Perfil!$A$6:$A$17,0)),""))
B17: =IF(A17="","",IFERROR(INDEX(Perfil!$B$6:$B$17,MATCH(A17,Perfil!$A$6:$A$17,0)),""))

Sheet Revisión semanal
A1: Revisión semanal (15 minutos por salón)
A2: Nota del 1 al 5 por módulo (vacío si no lo usó). Las columnas grises traen solas los números de esa semana.
A4: Semana (cualquier día) | B4: Salón | C4: ID en Lalan | D4: Chats | E4: Agenda | F4: Pantalla de Lalan | G4: Informes | H4: Caja | I4: Inventario | J4: Sala | K4: Lounge | L4: Nota promedio | M4: Horas que ahorró esta semana | N4: Lo que mejor funcionó | O4: Lo que falló o molestó | P4: Lo que pidió | Q4: Mensajes de clientas | R4: % que respondió Lalan | S4: Pases a persona | T4: Citas que agendó Lalan | U4: Minutos en la app | V4: Espera mediana del equipo (min)
A5: 46300 | B5: Salón Ejemplo | C5: =IF(B5="","",IFERROR(INDEX(Perfil!$B$6:$B$17,MATCH(B5,Perfil!$A$6:$A$17,0)),"")) | D5: 4 | E5: 5 | F5: 3 | G5: 4 | L5: =IF(COUNT(D5:K5)=0,"",AVERAGE(D5:K5)) | M5: 2 | N5: Lalan contestó de noche | O5: Dio un precio viejo | P5: Avisar cuando una clienta cancela | Q5: =IF(OR($A5="",$C5=""),"",SUMIFS('Datos diario'!$E:$E,'Datos diario'!$C:$C,$C5,'Datos diario'!$B:$B,$A5-WEEKDAY($A5,3))) | R5: =IF(OR($A5="",$C5=""),"",IFERROR(SUMIFS('Datos diario'!$F:$F,'Datos diario'!$C:$C,$C5,'Datos diario'!$B:$B,$A5-WEEKDAY($A5,3))/(SUMIFS('Datos diario'!$F:$F,'Datos diario'!$C:$C,$C5,'Datos diario'!$B:$B,$A5-WEEKDAY($A5,3))+SUMIFS('Datos diario'!$G:$G,'Datos diario'!$C:$C,$C5,'Datos diario'!$B:$B,$A5-WEEKDAY($A5,3))),"")) | S5: =IF(OR($A5="",$C5=""),"",SUMIFS('Datos diario'!$I:$I,'Datos diario'!$C:$C,$C5,'Datos diario'!$B:$B,$A5-WEEKDAY($A5,3))) | T5: =IF(OR($A5="",$C5=""),"",SUMIFS('Datos diario'!$P:$P,'Datos diario'!$C:$C,$C5,'Datos diario'!$B:$B,$A5-WEEKDAY($A5,3))) | U5: =IF(OR($A5="",$C5=""),"",ROUND(SUMIFS('Datos diario'!$U:$U,'Datos diario'!$C:$C,$C5,'Datos diario'!$B:$B,$A5-WEEKDAY($A5,3)),0)) | V5: =IF(OR($A5="",$C5=""),"",IFERROR(ROUND(AVERAGEIFS('Datos diario'!$M:$M,'Datos diario'!$C:$C,$C5,'Datos diario'!$B:$B,$A5-WEEKDAY($A5,3),'Datos diario'!$L:$L,">0"),1),""))
C6: =IF(B6="","",IFERROR(INDEX(Perfil!$B$6:$B$17,MATCH(B6,Perfil!$A$6:$A$17,0)),"")) | L6: =IF(COUNT(D6:K6)=0,"",AVERAGE(D6:K6)) | Q6: =IF(OR($A6="",$C6=""),"",SUMIFS('Datos diario'!$E:$E,'Datos diario'!$C:$C,$C6,'Datos diario'!$B:$B,$A6-WEEKDAY($A6,3))) | R6: =IF(OR($A6="",$C6=""),"",IFERROR(SUMIFS('Datos diario'!$F:$F,'Datos diario'!$C:$C,$C6,'Datos diario'!$B:$B,$A6-WEEKDAY($A6,3))/(SUMIFS('Datos diario'!$F:$F,'Datos diario'!$C:$C,$C6,'Datos diario'!$B:$B,$A6-WEEKDAY($A6,3))+SUMIFS('Datos diario'!$G:$G,'Datos diario'!$C:$C,$C6,'Datos diario'!$B:$B,$A6-WEEKDAY($A6,3))),"")) | S6: =IF(OR($A6="",$C6=""),"",SUMIFS('Datos diario'!$I:$I,'Datos diario'!$C:$C,$C6,'Datos diario'!$B:$B,$A6-WEEKDAY($A6,3))) | T6: =IF(OR($A6="",$C6=""),"",SUMIFS('Datos diario'!$P:$P,'Datos diario'!$C:$C,$C6,'Datos diario'!$B:$B,$A6-WEEKDAY($A6,3))) | U6: =IF(OR($A6="",$C6=""),"",ROUND(SUMIFS('Datos diario'!$U:$U,'Datos diario'!$C:$C,$C6,'Datos diario'!$B:$B,$A6-WEEKDAY($A6,3)),0)) | V6: =IF(OR($A6="",$C6=""),"",IFERROR(ROUND(AVERAGEIFS('Datos diario'!$M:$M,'Datos diario'!$C:$C,$C6,'Datos diario'!$B:$B,$A6-WEEKDAY($A6,3),'Datos diario'!$L:$L,">0"),1),""))
C7: =IF(B7="","",IFERROR(INDEX(Perfil!$B$6:$B$17,MATCH(B7,Perfil!$A$6:$A$17,0)),"")) | L7: =IF(COUNT(D7:K7)=0,"",AVERAGE(D7:K7)) | Q7: =IF(OR($A7="",$C7=""),"",SUMIFS('Datos diario'!$E:$E,'Datos diario'!$C:$C,$C7,'Datos diario'!$B:$B,$A7-WEEKDAY($A7,3))) | R7: =IF(OR($A7="",$C7=""),"",IFERROR(SUMIFS('Datos diario'!$F:$F,'Datos diario'!$C:$C,$C7,'Datos diario'!$B:$B,$A7-WEEKDAY($A7,3))/(SUMIFS('Datos diario'!$F:$F,'Datos diario'!$C:$C,$C7,'Datos diario'!$B:$B,$A7-WEEKDAY($A7,3))+SUMIFS('Datos diario'!$G:$G,'Datos diario'!$C:$C,$C7,'Datos diario'!$B:$B,$A7-WEEKDAY($A7,3))),"")) | S7: =IF(OR($A7="",$C7=""),"",SUMIFS('Datos diario'!$I:$I,'Datos diario'!$C:$C,$C7,'Datos diario'!$B:$B,$A7-WEEKDAY($A7,3))) | T7: =IF(OR($A7="",$C7=""),"",SUMIFS('Datos diario'!$P:$P,'Datos diario'!$C:$C,$C7,'Datos diario'!$B:$B,$A7-WEEKDAY($A7,3))) | U7: =IF(OR($A7="",$C7=""),"",ROUND(SUMIFS('Datos diario'!$U:$U,'Datos diario'!$C:$C,$C7,'Datos diario'!$B:$B,$A7-WEEKDAY($A7,3)),0)) | V7: =IF(OR($A7="",$C7=""),"",IFERROR(ROUND(AVERAGEIFS('Datos diario'!$M:$M,'Datos diario'!$C:$C,$C7,'Datos diario'!$B:$B,$A7-WEEKDAY($A7,3),'Datos diario'!$L:$L,">0"),1),""))
C8: =IF(B8="","",IFERROR(INDEX(Perfil!$B$6:$B$17,MATCH(B8,Perfil!$A$6:$A$17,0)),"")) | L8: =IF(COUNT(D8:K8)=0,"",AVERAGE(D8:K8)) | Q8: =IF(OR($A8="",$C8=""),"",SUMIFS('Datos diario'!$E:$E,'Datos diario'!$C:$C,$C8,'Datos diario'!$B:$B,$A8-WEEKDAY($A8,3))) | R8: =IF(OR($A8="",$C8=""),"",IFERROR(SUMIFS('Datos diario'!$F:$F,'Datos diario'!$C:$C,$C8,'Datos diario'!$B:$B,$A8-WEEKDAY($A8,3))/(SUMIFS('Datos diario'!$F:$F,'Datos diario'!$C:$C,$C8,'Datos diario'!$B:$B,$A8-WEEKDAY($A8,3))+SUMIFS('Datos diario'!$G:$G,'Datos diario'!$C:$C,$C8,'Datos diario'!$B:$B,$A8-WEEKDAY($A8,3))),"")) | S8: =IF(OR($A8="",$C8=""),"",SUMIFS('Datos diario'!$I:$I,'Datos diario'!$C:$C,$C8,'Datos diario'!$B:$B,$A8-WEEKDAY($A8,3))) | T8: =IF(OR($A8="",$C8=""),"",SUMIFS('Datos diario'!$P:$P,'Datos diario'!$C:$C,$C8,'Datos diario'!$B:$B,$A8-WEEKDAY($A8,3))) | U8: =IF(OR($A8="",$C8=""),"",ROUND(SUMIFS('Datos diario'!$U:$U,'Datos diario'!$C:$C,$C8,'Datos diario'!$B:$B,$A8-WEEKDAY($A8,3)),0)) | V8: =IF(OR($A8="",$C8=""),"",IFERROR(ROUND(AVERAGEIFS('Datos diario'!$M:$M,'Datos diario'!$C:$C,$C8,'Datos diario'!$B:$B,$A8-WEEKDAY($A8,3),'Datos diario'!$L:$L,">0"),1),""))
C9: =IF(B9="","",IFERROR(INDEX(Perfil!$B$6:$B$17,MATCH(B9,Perfil!$A$6:$A$17,0)),"")) | L9: =IF(COUNT(D9:K9)=0,"",AVERAGE(D9:K9)) | Q9: =IF(OR($A9="",$C9=""),"",SUMIFS('Datos diario'!$E:$E,'Datos diario'!$C:$C,$C9,'Datos diario'!$B:$B,$A9-WEEKDAY($A9,3))) | R9: =IF(OR($A9="",$C9=""),"",IFERROR(SUMIFS('Datos diario'!$F:$F,'Datos diario'!$C:$C,$C9,'Datos diario'!$B:$B,$A9-WEEKDAY($A9,3))/(SUMIFS('Datos diario'!$F:$F,'Datos diario'!$C:$C,$C9,'Datos diario'!$B:$B,$A9-WEEKDAY($A9,3))+SUMIFS('Datos diario'!$G:$G,'Datos diario'!$C:$C,$C9,'Datos diario'!$B:$B,$A9-WEEKDAY($A9,3))),"")) | S9: =IF(OR($A9="",$C9=""),"",SUMIFS('Datos diario'!$I:$I,'Datos diario'!$C:$C,$C9,'Datos diario'!$B:$B,$A9-WEEKDAY($A9,3))) | T9: =IF(OR($A9="",$C9=""),"",SUMIFS('Datos diario'!$P:$P,'Datos diario'!$C:$C,$C9,'Datos diario'!$B:$B,$A9-WEEKDAY($A9,3))) | U9: =IF(OR($A9="",$C9=""),"",ROUND(SUMIFS('Datos diario'!$U:$U,'Datos diario'!$C:$C,$C9,'Datos diario'!$B:$B,$A9-WEEKDAY($A9,3)),0)) | V9: =IF(OR($A9="",$C9=""),"",IFERROR(ROUND(AVERAGEIFS('Datos diario'!$M:$M,'Datos diario'!$C:$C,$C9,'Datos diario'!$B:$B,$A9-WEEKDAY($A9,3),'Datos diario'!$L:$L,">0"),1),""))
C10: =IF(B10="","",IFERROR(INDEX(Perfil!$B$6:$B$17,MATCH(B10,Perfil!$A$6:$A$17,0)),"")) | L10: =IF(COUNT(D10:K10)=0,"",AVERAGE(D10:K10)) | Q10: =IF(OR($A10="",$C10=""),"",SUMIFS('Datos diario'!$E:$E,'Datos diario'!$C:$C,$C10,'Datos diario'!$B:$B,$A10-WEEKDAY($A10,3))) | R10: =IF(OR($A10="",$C10=""),"",IFERROR(SUMIFS('Datos diario'!$F:$F,'Datos diario'!$C:$C,$C10,'Datos diario'!$B:$B,$A10-WEEKDAY($A10,3))/(SUMIFS('Datos diario'!$F:$F,'Datos diario'!$C:$C,$C10,'Datos diario'!$B:$B,$A10-WEEKDAY($A10,3))+SUMIFS('Datos diario'!$G:$G,'Datos diario'!$C:$C,$C10,'Datos diario'!$B:$B,$A10-WEEKDAY($A10,3))),"")) | S10: =IF(OR($A10="",$C10=""),"",SUMIFS('Datos diario'!$I:$I,'Datos diario'!$C:$C,$C10,'Datos diario'!$B:$B,$A10-WEEKDAY($A10,3))) | T10: =IF(OR($A10="",$C10=""),"",SUMIFS('Datos diario'!$P:$P,'Datos diario'!$C:$C,$C10,'Datos diario'!$B:$B,$A10-WEEKDAY($A10,3))) | U10: =IF(OR($A10="",$C10=""),"",ROUND(SUMIFS('Datos diario'!$U:$U,'Datos diario'!$C:$C,$C10,'Datos diario'!$B:$B,$A10-WEEKDAY($A10,3)),0)) | V10: =IF(OR($A10="",$C10=""),"",IFERROR(ROUND(AVERAGEIFS('Datos diario'!$M:$M,'Datos diario'!$C:$C,$C10,'Datos diario'!$B:$B,$A10-WEEKDAY($A10,3),'Datos diario'!$L:$L,">0"),1),""))
C11: =IF(B11="","",IFERROR(INDEX(Perfil!$B$6:$B$17,MATCH(B11,Perfil!$A$6:$A$17,0)),"")) | L11: =IF(COUNT(D11:K11)=0,"",AVERAGE(D11:K11)) | Q11: =IF(OR($A11="",$C11=""),"",SUMIFS('Datos diario'!$E:$E,'Datos diario'!$C:$C,$C11,'Datos diario'!$B:$B,$A11-WEEKDAY($A11,3))) | R11: =IF(OR($A11="",$C11=""),"",IFERROR(SUMIFS('Datos diario'!$F:$F,'Datos diario'!$C:$C,$C11,'Datos diario'!$B:$B,$A11-WEEKDAY($A11,3))/(SUMIFS('Datos diario'!$F:$F,'Datos diario'!$C:$C,$C11,'Datos diario'!$B:$B,$A11-WEEKDAY($A11,3))+SUMIFS('Datos diario'!$G:$G,'Datos diario'!$C:$C,$C11,'Datos diario'!$B:$B,$A11-WEEKDAY($A11,3))),"")) | S11: =IF(OR($A11="",$C11=""),"",SUMIFS('Datos diario'!$I:$I,'Datos diario'!$C:$C,$C11,'Datos diario'!$B:$B,$A11-WEEKDAY($A11,3))) | T11: =IF(OR($A11="",$C11=""),"",SUMIFS('Datos diario'!$P:$P,'Datos diario'!$C:$C,$C11,'Datos diario'!$B:$B,$A11-WEEKDAY($A11,3))) | U11: =IF(OR($A11="",$C11=""),"",ROUND(SUMIFS('Datos diario'!$U:$U,'Datos diario'!$C:$C,$C11,'Datos diario'!$B:$B,$A11-WEEKDAY($A11,3)),0)) | V11: =IF(OR($A11="",$C11=""),"",IFERROR(ROUND(AVERAGEIFS('Datos diario'!$M:$M,'Datos diario'!$C:$C,$C11,'Datos diario'!$B:$B,$A11-WEEKDAY($A11,3),'Datos diario'!$L:$L,">0"),1),""))
C12: =IF(B12="","",IFERROR(INDEX(Perfil!$B$6:$B$17,MATCH(B12,Perfil!$A$6:$A$17,0)),"")) | L12: =IF(COUNT(D12:K12)=0,"",AVERAGE(D12:K12)) | Q12: =IF(OR($A12="",$C12=""),"",SUMIFS('Datos diario'!$E:$E,'Datos diario'!$C:$C,$C12,'Datos diario'!$B:$B,$A12-WEEKDAY($A12,3))) | R12: =IF(OR($A12="",$C12=""),"",IFERROR(SUMIFS('Datos diario'!$F:$F,'Datos diario'!$C:$C,$C12,'Datos diario'!$B:$B,$A12-WEEKDAY($A12,3))/(SUMIFS('Datos diario'!$F:$F,'Datos diario'!$C:$C,$C12,'Datos diario'!$B:$B,$A12-WEEKDAY($A12,3))+SUMIFS('Datos diario'!$G:$G,'Datos diario'!$C:$C,$C12,'Datos diario'!$B:$B,$A12-WEEKDAY($A12,3))),"")) | S12: =IF(OR($A12="",$C12=""),"",SUMIFS('Datos diario'!$I:$I,'Datos diario'!$C:$C,$C12,'Datos diario'!$B:$B,$A12-WEEKDAY($A12,3))) | T12: =IF(OR($A12="",$C12=""),"",SUMIFS('Datos diario'!$P:$P,'Datos diario'!$C:$C,$C12,'Datos diario'!$B:$B,$A12-WEEKDAY($A12,3))) | U12: =IF(OR($A12="",$C12=""),"",ROUND(SUMIFS('Datos diario'!$U:$U,'Datos diario'!$C:$C,$C12,'Datos diario'!$B:$B,$A12-WEEKDAY($A12,3)),0)) | V12: =IF(OR($A12="",$C12=""),"",IFERROR(ROUND(AVERAGEIFS('Datos diario'!$M:$M,'Datos diario'!$C:$C,$C12,'Datos diario'!$B:$B,$A12-WEEKDAY($A12,3),'Datos diario'!$L:$L,">0"),1),""))
C13: =IF(B13="","",IFERROR(INDEX(Perfil!$B$6:$B$17,MATCH(B13,Perfil!$A$6:$A$17,0)),"")) | L13: =IF(COUNT(D13:K13)=0,"",AVERAGE(D13:K13)) | Q13: =IF(OR($A13="",$C13=""),"",SUMIFS('Datos diario'!$E:$E,'Datos diario'!$C:$C,$C13,'Datos diario'!$B:$B,$A13-WEEKDAY($A13,3))) | R13: =IF(OR($A13="",$C13=""),"",IFERROR(SUMIFS('Datos diario'!$F:$F,'Datos diario'!$C:$C,$C13,'Datos diario'!$B:$B,$A13-WEEKDAY($A13,3))/(SUMIFS('Datos diario'!$F:$F,'Datos diario'!$C:$C,$C13,'Datos diario'!$B:$B,$A13-WEEKDAY($A13,3))+SUMIFS('Datos diario'!$G:$G,'Datos diario'!$C:$C,$C13,'Datos diario'!$B:$B,$A13-WEEKDAY($A13,3))),"")) | S13: =IF(OR($A13="",$C13=""),"",SUMIFS('Datos diario'!$I:$I,'Datos diario'!$C:$C,$C13,'Datos diario'!$B:$B,$A13-WEEKDAY($A13,3))) | T13: =IF(OR($A13="",$C13=""),"",SUMIFS('Datos diario'!$P:$P,'Datos diario'!$C:$C,$C13,'Datos diario'!$B:$B,$A13-WEEKDAY($A13,3))) | U13: =IF(OR($A13="",$C13=""),"",ROUND(SUMIFS('Datos diario'!$U:$U,'Datos diario'!$C:$C,$C13,'Datos diario'!$B:$B,$A13-WEEKDAY($A13,3)),0)) | V13: =IF(OR($A13="",$C13=""),"",IFERROR(ROUND(AVERAGEIFS('Datos diario'!$M:$M,'Datos diario'!$C:$C,$C13,'Datos diario'!$B:$B,$A13-WEEKDAY($A13,3),'Datos diario'!$L:$L,">0"),1),""))
C14: =IF(B14="","",IFERROR(INDEX(Perfil!$B$6:$B$17,MATCH(B14,Perfil!$A$6:$A$17,0)),"")) | L14: =IF(COUNT(D14:K14)=0,"",AVERAGE(D14:K14)) | Q14: =IF(OR($A14="",$C14=""),"",SUMIFS('Datos diario'!$E:$E,'Datos diario'!$C:$C,$C14,'Datos diario'!$B:$B,$A14-WEEKDAY($A14,3))) | R14: =IF(OR($A14="",$C14=""),"",IFERROR(SUMIFS('Datos diario'!$F:$F,'Datos diario'!$C:$C,$C14,'Datos diario'!$B:$B,$A14-WEEKDAY($A14,3))/(SUMIFS('Datos diario'!$F:$F,'Datos diario'!$C:$C,$C14,'Datos diario'!$B:$B,$A14-WEEKDAY($A14,3))+SUMIFS('Datos diario'!$G:$G,'Datos diario'!$C:$C,$C14,'Datos diario'!$B:$B,$A14-WEEKDAY($A14,3))),"")) | S14: =IF(OR($A14="",$C14=""),"",SUMIFS('Datos diario'!$I:$I,'Datos diario'!$C:$C,$C14,'Datos diario'!$B:$B,$A14-WEEKDAY($A14,3))) | T14: =IF(OR($A14="",$C14=""),"",SUMIFS('Datos diario'!$P:$P,'Datos diario'!$C:$C,$C14,'Datos diario'!$B:$B,$A14-WEEKDAY($A14,3))) | U14: =IF(OR($A14="",$C14=""),"",ROUND(SUMIFS('Datos diario'!$U:$U,'Datos diario'!$C:$C,$C14,'Datos diario'!$B:$B,$A14-WEEKDAY($A14,3)),0)) | V14: =IF(OR($A14="",$C14=""),"",IFERROR(ROUND(AVERAGEIFS('Datos diario'!$M:$M,'Datos diario'!$C:$C,$C14,'Datos diario'!$B:$B,$A14-WEEKDAY($A14,3),'Datos diario'!$L:$L,">0"),1),""))
C15: =IF(B15="","",IFERROR(INDEX(Perfil!$B$6:$B$17,MATCH(B15,Perfil!$A$6:$A$17,0)),"")) | L15: =IF(COUNT(D15:K15)=0,"",AVERAGE(D15:K15)) | Q15: =IF(OR($A15="",$C15=""),"",SUMIFS('Datos diario'!$E:$E,'Datos diario'!$C:$C,$C15,'Datos diario'!$B:$B,$A15-WEEKDAY($A15,3))) | R15: =IF(OR($A15="",$C15=""),"",IFERROR(SUMIFS('Datos diario'!$F:$F,'Datos diario'!$C:$C,$C15,'Datos diario'!$B:$B,$A15-WEEKDAY($A15,3))/(SUMIFS('Datos diario'!$F:$F,'Datos diario'!$C:$C,$C15,'Datos diario'!$B:$B,$A15-WEEKDAY($A15,3))+SUMIFS('Datos diario'!$G:$G,'Datos diario'!$C:$C,$C15,'Datos diario'!$B:$B,$A15-WEEKDAY($A15,3))),"")) | S15: =IF(OR($A15="",$C15=""),"",SUMIFS('Datos diario'!$I:$I,'Datos diario'!$C:$C,$C15,'Datos diario'!$B:$B,$A15-WEEKDAY($A15,3))) | T15: =IF(OR($A15="",$C15=""),"",SUMIFS('Datos diario'!$P:$P,'Datos diario'!$C:$C,$C15,'Datos diario'!$B:$B,$A15-WEEKDAY($A15,3))) | U15: =IF(OR($A15="",$C15=""),"",ROUND(SUMIFS('Datos diario'!$U:$U,'Datos diario'!$C:$C,$C15,'Datos diario'!$B:$B,$A15-WEEKDAY($A15,3)),0)) | V15: =IF(OR($A15="",$C15=""),"",IFERROR(ROUND(AVERAGEIFS('Datos diario'!$M:$M,'Datos diario'!$C:$C,$C15,'Datos diario'!$B:$B,$A15-WEEKDAY($A15,3),'Datos diario'!$L:$L,">0"),1),""))
C16: =IF(B16="","",IFERROR(INDEX(Perfil!$B$6:$B$17,MATCH(B16,Perfil!$A$6:$A$17,0)),"")) | L16: =IF(COUNT(D16:K16)=0,"",AVERAGE(D16:K16)) | Q16: =IF(OR($A16="",$C16=""),"",SUMIFS('Datos diario'!$E:$E,'Datos diario'!$C:$C,$C16,'Datos diario'!$B:$B,$A16-WEEKDAY($A16,3))) | R16: =IF(OR($A16="",$C16=""),"",IFERROR(SUMIFS('Datos diario'!$F:$F,'Datos diario'!$C:$C,$C16,'Datos diario'!$B:$B,$A16-WEEKDAY($A16,3))/(SUMIFS('Datos diario'!$F:$F,'Datos diario'!$C:$C,$C16,'Datos diario'!$B:$B,$A16-WEEKDAY($A16,3))+SUMIFS('Datos diario'!$G:$G,'Datos diario'!$C:$C,$C16,'Datos diario'!$B:$B,$A16-WEEKDAY($A16,3))),"")) | S16: =IF(OR($A16="",$C16=""),"",SUMIFS('Datos diario'!$I:$I,'Datos diario'!$C:$C,$C16,'Datos diario'!$B:$B,$A16-WEEKDAY($A16,3))) | T16: =IF(OR($A16="",$C16=""),"",SUMIFS('Datos diario'!$P:$P,'Datos diario'!$C:$C,$C16,'Datos diario'!$B:$B,$A16-WEEKDAY($A16,3))) | U16: =IF(OR($A16="",$C16=""),"",ROUND(SUMIFS('Datos diario'!$U:$U,'Datos diario'!$C:$C,$C16,'Datos diario'!$B:$B,$A16-WEEKDAY($A16,3)),0)) | V16: =IF(OR($A16="",$C16=""),"",IFERROR(ROUND(AVERAGEIFS('Datos diario'!$M:$M,'Datos diario'!$C:$C,$C16,'Datos diario'!$B:$B,$A16-WEEKDAY($A16,3),'Datos diario'!$L:$L,">0"),1),""))
C17: =IF(B17="","",IFERROR(INDEX(Perfil!$B$6:$B$17,MATCH(B17,Perfil!$A$6:$A$17,0)),"")) | L17: =IF(COUNT(D17:K17)=0,"",AVERAGE(D17:K17)) | Q17: =IF(OR($A17="",$C17=""),"",SUMIFS('Datos diario'!$E:$E,'Datos diario'!$C:$C,$C17,'Datos diario'!$B:$B,$A17-WEEKDAY($A17,3))) | R17: =IF(OR($A17="",$C17=""),"",IFERROR(SUMIFS('Datos diario'!$F:$F,'Datos diario'!$C:$C,$C17,'Datos diario'!$B:$B,$A17-WEEKDAY($A17,3))/(SUMIFS('Datos diario'!$F:$F,'Datos diario'!$C:$C,$C17,'Datos diario'!$B:$B,$A17-WEEKDAY($A17,3))+SUMIFS('Datos diario'!$G:$G,'Datos diario'!$C:$C,$C17,'Datos diario'!$B:$B,$A17-WEEKDAY($A17,3))),"")) | S17: =IF(OR($A17="",$C17=""),"",SUMIFS('Datos diario'!$I:$I,'Datos diario'!$C:$C,$C17,'Datos diario'!$B:$B,$A17-WEEKDAY($A17,3))) | T17: =IF(OR($A17="",$C17=""),"",SUMIFS('Datos diario'!$P:$P,'Datos diario'!$C:$C,$C17,'Datos diario'!$B:$B,$A17-WEEKDAY($A17,3))) | U17: =IF(OR($A17="",$C17=""),"",ROUND(SUMIFS('Datos diario'!$U:$U,'Datos diario'!$C:$C,$C17,'Datos diario'!$B:$B,$A17-WEEKDAY($A17,3)),0)) | V17: =IF(OR($A17="",$C17=""),"",IFERROR(ROUND(AVERAGEIFS('Datos diario'!$M:$M,'Datos diario'!$C:$C,$C17,'Datos diario'!$B:$B,$A17-WEEKDAY($A17,3),'Datos diario'!$L:$L,">0"),1),""))
... C205: =IF(B205="","",IFERROR(INDEX(Perfil!$B$6:$B$17,MATCH(B205,Perfil!$A$6:$A$17,0)),"")) | L205: =IF(COUNT(D205:K205)=0,"",AVERAGE(D205:K205)) | Q205: =IF(OR($A205="",$C205=""),"",SUMIFS('Datos diario'!$E:$E,'Datos diario'!$C:$C,$C205,'Datos diario'!$B:$B,$A205-WEEKDAY($A205,3))) | R205: =IF(OR($A205="",$C205=""),"",IFERROR(SUMIFS('Datos diario'!$F:$F,'Datos diario'!$C:$C,$C205,'Datos diario'!$B:$B,$A205-WEEKDAY($A205,3))/(SUMIFS('Datos diario'!$F:$F,'Datos diario'!$C:$C,$C205,'Datos diario'!$B:$B,$A205-WEEKDAY($A205,3))+SUMIFS('Datos diario'!$G:$G,'Datos diario'!$C:$C,$C205,'Datos diario'!$B:$B,$A205-WEEKDAY($A205,3))),"")) | S205: =IF(OR($A205="",$C205=""),"",SUMIFS('Datos diario'!$I:$I,'Datos diario'!$C:$C,$C205,'Datos diario'!$B:$B,$A205-WEEKDAY($A205,3))) | T205: =IF(OR($A205="",$C205=""),"",SUMIFS('Datos diario'!$P:$P,'Datos diario'!$C:$C,$C205,'Datos diario'!$B:$B,$A205-WEEKDAY($A205,3))) | U205: =IF(OR($A205="",$C205=""),"",ROUND(SUMIFS('Datos diario'!$U:$U,'Datos diario'!$C:$C,$C205,'Datos diario'!$B:$B,$A205-WEEKDAY($A205,3)),0)) | V205: =IF(OR($A205="",$C205=""),"",IFERROR(ROUND(AVERAGEIFS('Datos diario'!$M:$M,'Datos diario'!$C:$C,$C205,'Datos diario'!$B:$B,$A205-WEEKDAY($A205,3),'Datos diario'!$L:$L,">0"),1),""))

Sheet Clientas
A1: Encuesta a clientas
A2: Pega aquí las respuestas del formulario (preguntas en la hoja Formularios). Anónima: sin nombre ni teléfono.
A4: Fecha | B4: Salón | C4: Canal | D4: Le respondieron rápido (1-5) | E4: Le resolvieron lo que pedía | F4: Notó que era una asistente | G4: Satisfacción general (1-5) | H4: Volvería a escribir por ahí | I4: Comentario
A5: 46303 | B5: Salón Ejemplo | C5: WhatsApp | D5: 5 | E5: Sí | F5: No | G5: 5 | H5: Sí | I5: Me contestaron a las 11 de la noche

Sheet Equipo
A1: Encuesta al equipo del salón
A2: Dueña, administración, recepción y especialistas. Una fila por persona y por vez que la contesta.
A4: Fecha | B4: Salón | C4: Rol | D4: Facilidad de uso (1-5) | E4: Tiempo que le ahorra (1-5) | F4: Confianza en lo que responde Lalan (1-5) | G4: Lo que más usa | H4: Lo que menos entiende | I4: Qué cambiaría
A5: 46310 | B5: Salón Ejemplo | C5: Recepción | D5: 4 | E5: 4 | F5: 3 | G5: Chats | H5: Cómo pasar un chat a Lalan otra vez | I5: Ver las citas del día en grande

Sheet Cierre
A1: Entrevista de cierre
A2: Al terminar el piloto, con cada dueña.
A4: Fecha | B4: Salón | C4: ¿Qué tan probable es que recomiende Lalan? (0-10) | D4: Tipo | E4: ¿Seguiría con Lalan? | F4: Cuánto pagaría al mes (RD$) | G4: Plan que elegiría | H4: Módulo más valioso | I4: Módulo que no usó | J4: Lo que le faltó | K4: Testimonio (sus palabras) | L4: ¿Permite usar su nombre y testimonio?
A5: 46376 | B5: Salón Ejemplo | C5: 9 | D5: =IF(C5="","",IF(C5>=9,"Promotora",IF(C5>=7,"Pasiva","Detractora"))) | E5: Sí | F5: 1200 | G5: Salón | H5: Chats | I5: Inventario | J5: Recordatorios por voz | K5: Ya no contesto WhatsApp de noche: Lalan agenda sola. | L5: Sí
D6: =IF(C6="","",IF(C6>=9,"Promotora",IF(C6>=7,"Pasiva","Detractora")))
D7: =IF(C7="","",IF(C7>=9,"Promotora",IF(C7>=7,"Pasiva","Detractora")))
D8: =IF(C8="","",IF(C8>=9,"Promotora",IF(C8>=7,"Pasiva","Detractora")))
D9: =IF(C9="","",IF(C9>=9,"Promotora",IF(C9>=7,"Pasiva","Detractora")))
D10: =IF(C10="","",IF(C10>=9,"Promotora",IF(C10>=7,"Pasiva","Detractora")))
D11: =IF(C11="","",IF(C11>=9,"Promotora",IF(C11>=7,"Pasiva","Detractora")))
D12: =IF(C12="","",IF(C12>=9,"Promotora",IF(C12>=7,"Pasiva","Detractora")))
D13: =IF(C13="","",IF(C13>=9,"Promotora",IF(C13>=7,"Pasiva","Detractora")))
D14: =IF(C14="","",IF(C14>=9,"Promotora",IF(C14>=7,"Pasiva","Detractora")))
D15: =IF(C15="","",IF(C15>=9,"Promotora",IF(C15>=7,"Pasiva","Detractora")))
D16: =IF(C16="","",IF(C16>=9,"Promotora",IF(C16>=7,"Pasiva","Detractora")))
D17: =IF(C17="","",IF(C17>=9,"Promotora",IF(C17>=7,"Pasiva","Detractora")))

Sheet Análisis
A1: Análisis del piloto
A2: Lo que dicen las dueñas al lado de lo que muestran los números. Actualiza los datos (Datos → Actualizar todo) antes de mirar.
A4: Resumen
A5: Salones en el piloto | D5: Mensajes de clientas | G5: % que respondió Lalan | J5: Citas que agendó Lalan
A6: =COUNTIF(Perfil!$Q$6:$Q$17,"Sí") | D6: =SUM('Datos diario'!$E:$E) | G6: =IFERROR(SUM('Datos diario'!$F:$F)/(SUM('Datos diario'!$F:$F)+SUM('Datos diario'!$G:$G)),"") | J6: =SUM('Datos diario'!$P:$P)
A7: NPS del piloto (-100 a 100) | D7: Pagarían al mes, promedio (RD$) | G7: Satisfacción de clientas (1-5) | J7: Respuestas de clientas
A8: =IFERROR(ROUND((COUNTIF(Cierre!$C$6:$C$17,">=9")-COUNTIF(Cierre!$C$6:$C$17,"<=6"))/COUNT(Cierre!$C$6:$C$17)*100,0),"") | D8: =IFERROR(AVERAGE(Cierre!$F$6:$F$17),"") | G8: =IFERROR(AVERAGE(Clientas!$G$6:$G$405),"") | J8: =COUNT(Clientas!$G$6:$G$405)
A10: Por salón
A11: Salón | B11: ID | C11: Seleccionado | D11: Días con datos | E11: Días usando la app | F11: Mensajes de clientas | G11: % que respondió Lalan | H11: Pases a persona por 100 mensajes | I11: Espera del equipo hoy (min) | J11: Antes: minutos para responder | K11: Citas que agendó Lalan | L11: % de citas por Lalan | M11: % de citas sin marcar | N11: Antes: faltas por semana | O11: Minutos de app por día activo | P11: Preguntas a Lalan | Q11: % informes abiertos | R11: Nota semanal promedio (1-5) | S11: Horas ahorradas por semana | T11: Antes: horas por semana en WhatsApp | U11: Satisfacción de sus clientas | V11: Facilidad para su equipo | W11: NPS | X11: Pagaría al mes (RD$) | Y11: Lectura
A12: =IF(Perfil!$A$6="","",Perfil!$A$6) | B12: =IF(OR($A12="",Perfil!$B$6="no está en Lalan"),"",Perfil!$B$6) | C12: =IF($A12="","",IF(Perfil!$Q$6="","—",Perfil!$Q$6)) | D12: =IF($B12="","",COUNTIFS('Datos diario'!$C:$C,$B12)) | E12: =IF($B12="","",COUNTIFS('Datos diario'!$C:$C,$B12,'Datos diario'!$U:$U,">0")) | F12: =IF($B12="","",SUMIFS('Datos diario'!$E:$E,'Datos diario'!$C:$C,$B12)) | G12: =IF($B12="","",IFERROR(SUMIFS('Datos diario'!$F:$F,'Datos diario'!$C:$C,$B12)/(SUMIFS('Datos diario'!$F:$F,'Datos diario'!$C:$C,$B12)+SUMIFS('Datos diario'!$G:$G,'Datos diario'!$C:$C,$B12)),"")) | H12: =IF($B12="","",IFERROR(SUMIFS('Datos diario'!$I:$I,'Datos diario'!$C:$C,$B12)/SUMIFS('Datos diario'!$E:$E,'Datos diario'!$C:$C,$B12)*100,"")) | I12: =IF($B12="","",IFERROR(AVERAGEIFS('Datos diario'!$M:$M,'Datos diario'!$C:$C,$B12,'Datos diario'!$L:$L,">0"),"")) | J12: =IF($A12="","",IFERROR(IF(INDEX('Línea base'!$F$6:$F$17,MATCH($A12,'Línea base'!$A$6:$A$17,0))="","",INDEX('Línea base'!$F$6:$F$17,MATCH($A12,'Línea base'!$A$6:$A$17,0))),"")) | K12: =IF($B12="","",SUMIFS('Datos diario'!$P:$P,'Datos diario'!$C:$C,$B12)) | L12: =IF($B12="","",IFERROR(SUMIFS('Datos diario'!$P:$P,'Datos diario'!$C:$C,$B12)/SUMIFS('Datos diario'!$O:$O,'Datos diario'!$C:$C,$B12),"")) | M12: =IF($B12="","",IFERROR(SUMIFS('Datos diario'!$T:$T,'Datos diario'!$C:$C,$B12)/SUMIFS('Datos diario'!$Q:$Q,'Datos diario'!$C:$C,$B12),"")) | N12: =IF($A12="","",IFERROR(IF(INDEX('Línea base'!$H$6:$H$17,MATCH($A12,'Línea base'!$A$6:$A$17,0))="","",INDEX('Línea base'!$H$6:$H$17,MATCH($A12,'Línea base'!$A$6:$A$17,0))),"")) | O12: =IF($B12="","",IFERROR(SUMIFS('Datos diario'!$U:$U,'Datos diario'!$C:$C,$B12)/E12,"")) | P12: =IF($B12="","",SUMIFS('Datos diario'!$X:$X,'Datos diario'!$C:$C,$B12)) | Q12: =IF($B12="","",IFERROR(SUMIFS('Datos diario'!$AB:$AB,'Datos diario'!$C:$C,$B12)/SUMIFS('Datos diario'!$AA:$AA,'Datos diario'!$C:$C,$B12),"")) | R12: =IF($A12="","",IFERROR(AVERAGEIFS('Revisión semanal'!$L$6:$L$205,'Revisión semanal'!$B$6:$B$205,$A12),"")) | S12: =IF($A12="","",IFERROR(AVERAGEIFS('Revisión semanal'!$M$6:$M$205,'Revisión semanal'!$B$6:$B$205,$A12),"")) | T12: =IF($A12="","",IFERROR(IF(INDEX('Línea base'!$D$6:$D$17,MATCH($A12,'Línea base'!$A$6:$A$17,0))="","",INDEX('Línea base'!$D$6:$D$17,MATCH($A12,'Línea base'!$A$6:$A$17,0))),"")) | U12: =IF($A12="","",IFERROR(AVERAGEIFS('Clientas'!$G$6:$G$405,'Clientas'!$B$6:$B$405,$A12),"")) | V12: =IF($A12="","",IFERROR(AVERAGEIFS('Equipo'!$D$6:$D$155,'Equipo'!$B$6:$B$155,$A12),"")) | W12: =IF($A12="","",IFERROR(IF(INDEX('Cierre'!$C$6:$C$17,MATCH($A12,'Cierre'!$B$6:$B$17,0))="","",INDEX('Cierre'!$C$6:$C$17,MATCH($A12,'Cierre'!$B$6:$B$17,0))),"")) | X12: =IF($A12="","",IFERROR(IF(INDEX('Cierre'!$F$6:$F$17,MATCH($A12,'Cierre'!$B$6:$B$17,0))="","",INDEX('Cierre'!$F$6:$F$17,MATCH($A12,'Cierre'!$B$6:$B$17,0))),"")) | Y12: =IF($A12="","",IF(W12="","Sin cierre todavía",IF(AND(W12>=9,N(G12)>=0.6),"Testimonio: pídeselo",IF(W12<=6,"Riesgo: entender por qué","Seguir midiendo"))))
A13: =IF(Perfil!$A$7="","",Perfil!$A$7) | B13: =IF(OR($A13="",Perfil!$B$7="no está en Lalan"),"",Perfil!$B$7) | C13: =IF($A13="","",IF(Perfil!$Q$7="","—",Perfil!$Q$7)) | D13: =IF($B13="","",COUNTIFS('Datos diario'!$C:$C,$B13)) | E13: =IF($B13="","",COUNTIFS('Datos diario'!$C:$C,$B13,'Datos diario'!$U:$U,">0")) | F13: =IF($B13="","",SUMIFS('Datos diario'!$E:$E,'Datos diario'!$C:$C,$B13)) | G13: =IF($B13="","",IFERROR(SUMIFS('Datos diario'!$F:$F,'Datos diario'!$C:$C,$B13)/(SUMIFS('Datos diario'!$F:$F,'Datos diario'!$C:$C,$B13)+SUMIFS('Datos diario'!$G:$G,'Datos diario'!$C:$C,$B13)),"")) | H13: =IF($B13="","",IFERROR(SUMIFS('Datos diario'!$I:$I,'Datos diario'!$C:$C,$B13)/SUMIFS('Datos diario'!$E:$E,'Datos diario'!$C:$C,$B13)*100,"")) | I13: =IF($B13="","",IFERROR(AVERAGEIFS('Datos diario'!$M:$M,'Datos diario'!$C:$C,$B13,'Datos diario'!$L:$L,">0"),"")) | J13: =IF($A13="","",IFERROR(IF(INDEX('Línea base'!$F$6:$F$17,MATCH($A13,'Línea base'!$A$6:$A$17,0))="","",INDEX('Línea base'!$F$6:$F$17,MATCH($A13,'Línea base'!$A$6:$A$17,0))),"")) | K13: =IF($B13="","",SUMIFS('Datos diario'!$P:$P,'Datos diario'!$C:$C,$B13)) | L13: =IF($B13="","",IFERROR(SUMIFS('Datos diario'!$P:$P,'Datos diario'!$C:$C,$B13)/SUMIFS('Datos diario'!$O:$O,'Datos diario'!$C:$C,$B13),"")) | M13: =IF($B13="","",IFERROR(SUMIFS('Datos diario'!$T:$T,'Datos diario'!$C:$C,$B13)/SUMIFS('Datos diario'!$Q:$Q,'Datos diario'!$C:$C,$B13),"")) | N13: =IF($A13="","",IFERROR(IF(INDEX('Línea base'!$H$6:$H$17,MATCH($A13,'Línea base'!$A$6:$A$17,0))="","",INDEX('Línea base'!$H$6:$H$17,MATCH($A13,'Línea base'!$A$6:$A$17,0))),"")) | O13: =IF($B13="","",IFERROR(SUMIFS('Datos diario'!$U:$U,'Datos diario'!$C:$C,$B13)/E13,"")) | P13: =IF($B13="","",SUMIFS('Datos diario'!$X:$X,'Datos diario'!$C:$C,$B13)) | Q13: =IF($B13="","",IFERROR(SUMIFS('Datos diario'!$AB:$AB,'Datos diario'!$C:$C,$B13)/SUMIFS('Datos diario'!$AA:$AA,'Datos diario'!$C:$C,$B13),"")) | R13: =IF($A13="","",IFERROR(AVERAGEIFS('Revisión semanal'!$L$6:$L$205,'Revisión semanal'!$B$6:$B$205,$A13),"")) | S13: =IF($A13="","",IFERROR(AVERAGEIFS('Revisión semanal'!$M$6:$M$205,'Revisión semanal'!$B$6:$B$205,$A13),"")) | T13: =IF($A13="","",IFERROR(IF(INDEX('Línea base'!$D$6:$D$17,MATCH($A13,'Línea base'!$A$6:$A$17,0))="","",INDEX('Línea base'!$D$6:$D$17,MATCH($A13,'Línea base'!$A$6:$A$17,0))),"")) | U13: =IF($A13="","",IFERROR(AVERAGEIFS('Clientas'!$G$6:$G$405,'Clientas'!$B$6:$B$405,$A13),"")) | V13: =IF($A13="","",IFERROR(AVERAGEIFS('Equipo'!$D$6:$D$155,'Equipo'!$B$6:$B$155,$A13),"")) | W13: =IF($A13="","",IFERROR(IF(INDEX('Cierre'!$C$6:$C$17,MATCH($A13,'Cierre'!$B$6:$B$17,0))="","",INDEX('Cierre'!$C$6:$C$17,MATCH($A13,'Cierre'!$B$6:$B$17,0))),"")) | X13: =IF($A13="","",IFERROR(IF(INDEX('Cierre'!$F$6:$F$17,MATCH($A13,'Cierre'!$B$6:$B$17,0))="","",INDEX('Cierre'!$F$6:$F$17,MATCH($A13,'Cierre'!$B$6:$B$17,0))),"")) | Y13: =IF($A13="","",IF(W13="","Sin cierre todavía",IF(AND(W13>=9,N(G13)>=0.6),"Testimonio: pídeselo",IF(W13<=6,"Riesgo: entender por qué","Seguir midiendo"))))
A14: =IF(Perfil!$A$8="","",Perfil!$A$8) | B14: =IF(OR($A14="",Perfil!$B$8="no está en Lalan"),"",Perfil!$B$8) | C14: =IF($A14="","",IF(Perfil!$Q$8="","—",Perfil!$Q$8)) | D14: =IF($B14="","",COUNTIFS('Datos diario'!$C:$C,$B14)) | E14: =IF($B14="","",COUNTIFS('Datos diario'!$C:$C,$B14,'Datos diario'!$U:$U,">0")) | F14: =IF($B14="","",SUMIFS('Datos diario'!$E:$E,'Datos diario'!$C:$C,$B14)) | G14: =IF($B14="","",IFERROR(SUMIFS('Datos diario'!$F:$F,'Datos diario'!$C:$C,$B14)/(SUMIFS('Datos diario'!$F:$F,'Datos diario'!$C:$C,$B14)+SUMIFS('Datos diario'!$G:$G,'Datos diario'!$C:$C,$B14)),"")) | H14: =IF($B14="","",IFERROR(SUMIFS('Datos diario'!$I:$I,'Datos diario'!$C:$C,$B14)/SUMIFS('Datos diario'!$E:$E,'Datos diario'!$C:$C,$B14)*100,"")) | I14: =IF($B14="","",IFERROR(AVERAGEIFS('Datos diario'!$M:$M,'Datos diario'!$C:$C,$B14,'Datos diario'!$L:$L,">0"),"")) | J14: =IF($A14="","",IFERROR(IF(INDEX('Línea base'!$F$6:$F$17,MATCH($A14,'Línea base'!$A$6:$A$17,0))="","",INDEX('Línea base'!$F$6:$F$17,MATCH($A14,'Línea base'!$A$6:$A$17,0))),"")) | K14: =IF($B14="","",SUMIFS('Datos diario'!$P:$P,'Datos diario'!$C:$C,$B14)) | L14: =IF($B14="","",IFERROR(SUMIFS('Datos diario'!$P:$P,'Datos diario'!$C:$C,$B14)/SUMIFS('Datos diario'!$O:$O,'Datos diario'!$C:$C,$B14),"")) | M14: =IF($B14="","",IFERROR(SUMIFS('Datos diario'!$T:$T,'Datos diario'!$C:$C,$B14)/SUMIFS('Datos diario'!$Q:$Q,'Datos diario'!$C:$C,$B14),"")) | N14: =IF($A14="","",IFERROR(IF(INDEX('Línea base'!$H$6:$H$17,MATCH($A14,'Línea base'!$A$6:$A$17,0))="","",INDEX('Línea base'!$H$6:$H$17,MATCH($A14,'Línea base'!$A$6:$A$17,0))),"")) | O14: =IF($B14="","",IFERROR(SUMIFS('Datos diario'!$U:$U,'Datos diario'!$C:$C,$B14)/E14,"")) | P14: =IF($B14="","",SUMIFS('Datos diario'!$X:$X,'Datos diario'!$C:$C,$B14)) | Q14: =IF($B14="","",IFERROR(SUMIFS('Datos diario'!$AB:$AB,'Datos diario'!$C:$C,$B14)/SUMIFS('Datos diario'!$AA:$AA,'Datos diario'!$C:$C,$B14),"")) | R14: =IF($A14="","",IFERROR(AVERAGEIFS('Revisión semanal'!$L$6:$L$205,'Revisión semanal'!$B$6:$B$205,$A14),"")) | S14: =IF($A14="","",IFERROR(AVERAGEIFS('Revisión semanal'!$M$6:$M$205,'Revisión semanal'!$B$6:$B$205,$A14),"")) | T14: =IF($A14="","",IFERROR(IF(INDEX('Línea base'!$D$6:$D$17,MATCH($A14,'Línea base'!$A$6:$A$17,0))="","",INDEX('Línea base'!$D$6:$D$17,MATCH($A14,'Línea base'!$A$6:$A$17,0))),"")) | U14: =IF($A14="","",IFERROR(AVERAGEIFS('Clientas'!$G$6:$G$405,'Clientas'!$B$6:$B$405,$A14),"")) | V14: =IF($A14="","",IFERROR(AVERAGEIFS('Equipo'!$D$6:$D$155,'Equipo'!$B$6:$B$155,$A14),"")) | W14: =IF($A14="","",IFERROR(IF(INDEX('Cierre'!$C$6:$C$17,MATCH($A14,'Cierre'!$B$6:$B$17,0))="","",INDEX('Cierre'!$C$6:$C$17,MATCH($A14,'Cierre'!$B$6:$B$17,0))),"")) | X14: =IF($A14="","",IFERROR(IF(INDEX('Cierre'!$F$6:$F$17,MATCH($A14,'Cierre'!$B$6:$B$17,0))="","",INDEX('Cierre'!$F$6:$F$17,MATCH($A14,'Cierre'!$B$6:$B$17,0))),"")) | Y14: =IF($A14="","",IF(W14="","Sin cierre todavía",IF(AND(W14>=9,N(G14)>=0.6),"Testimonio: pídeselo",IF(W14<=6,"Riesgo: entender por qué","Seguir midiendo"))))
A15: =IF(Perfil!$A$9="","",Perfil!$A$9) | B15: =IF(OR($A15="",Perfil!$B$9="no está en Lalan"),"",Perfil!$B$9) | C15: =IF($A15="","",IF(Perfil!$Q$9="","—",Perfil!$Q$9)) | D15: =IF($B15="","",COUNTIFS('Datos diario'!$C:$C,$B15)) | E15: =IF($B15="","",COUNTIFS('Datos diario'!$C:$C,$B15,'Datos diario'!$U:$U,">0")) | F15: =IF($B15="","",SUMIFS('Datos diario'!$E:$E,'Datos diario'!$C:$C,$B15)) | G15: =IF($B15="","",IFERROR(SUMIFS('Datos diario'!$F:$F,'Datos diario'!$C:$C,$B15)/(SUMIFS('Datos diario'!$F:$F,'Datos diario'!$C:$C,$B15)+SUMIFS('Datos diario'!$G:$G,'Datos diario'!$C:$C,$B15)),"")) | H15: =IF($B15="","",IFERROR(SUMIFS('Datos diario'!$I:$I,'Datos diario'!$C:$C,$B15)/SUMIFS('Datos diario'!$E:$E,'Datos diario'!$C:$C,$B15)*100,"")) | I15: =IF($B15="","",IFERROR(AVERAGEIFS('Datos diario'!$M:$M,'Datos diario'!$C:$C,$B15,'Datos diario'!$L:$L,">0"),"")) | J15: =IF($A15="","",IFERROR(IF(INDEX('Línea base'!$F$6:$F$17,MATCH($A15,'Línea base'!$A$6:$A$17,0))="","",INDEX('Línea base'!$F$6:$F$17,MATCH($A15,'Línea base'!$A$6:$A$17,0))),"")) | K15: =IF($B15="","",SUMIFS('Datos diario'!$P:$P,'Datos diario'!$C:$C,$B15)) | L15: =IF($B15="","",IFERROR(SUMIFS('Datos diario'!$P:$P,'Datos diario'!$C:$C,$B15)/SUMIFS('Datos diario'!$O:$O,'Datos diario'!$C:$C,$B15),"")) | M15: =IF($B15="","",IFERROR(SUMIFS('Datos diario'!$T:$T,'Datos diario'!$C:$C,$B15)/SUMIFS('Datos diario'!$Q:$Q,'Datos diario'!$C:$C,$B15),"")) | N15: =IF($A15="","",IFERROR(IF(INDEX('Línea base'!$H$6:$H$17,MATCH($A15,'Línea base'!$A$6:$A$17,0))="","",INDEX('Línea base'!$H$6:$H$17,MATCH($A15,'Línea base'!$A$6:$A$17,0))),"")) | O15: =IF($B15="","",IFERROR(SUMIFS('Datos diario'!$U:$U,'Datos diario'!$C:$C,$B15)/E15,"")) | P15: =IF($B15="","",SUMIFS('Datos diario'!$X:$X,'Datos diario'!$C:$C,$B15)) | Q15: =IF($B15="","",IFERROR(SUMIFS('Datos diario'!$AB:$AB,'Datos diario'!$C:$C,$B15)/SUMIFS('Datos diario'!$AA:$AA,'Datos diario'!$C:$C,$B15),"")) | R15: =IF($A15="","",IFERROR(AVERAGEIFS('Revisión semanal'!$L$6:$L$205,'Revisión semanal'!$B$6:$B$205,$A15),"")) | S15: =IF($A15="","",IFERROR(AVERAGEIFS('Revisión semanal'!$M$6:$M$205,'Revisión semanal'!$B$6:$B$205,$A15),"")) | T15: =IF($A15="","",IFERROR(IF(INDEX('Línea base'!$D$6:$D$17,MATCH($A15,'Línea base'!$A$6:$A$17,0))="","",INDEX('Línea base'!$D$6:$D$17,MATCH($A15,'Línea base'!$A$6:$A$17,0))),"")) | U15: =IF($A15="","",IFERROR(AVERAGEIFS('Clientas'!$G$6:$G$405,'Clientas'!$B$6:$B$405,$A15),"")) | V15: =IF($A15="","",IFERROR(AVERAGEIFS('Equipo'!$D$6:$D$155,'Equipo'!$B$6:$B$155,$A15),"")) | W15: =IF($A15="","",IFERROR(IF(INDEX('Cierre'!$C$6:$C$17,MATCH($A15,'Cierre'!$B$6:$B$17,0))="","",INDEX('Cierre'!$C$6:$C$17,MATCH($A15,'Cierre'!$B$6:$B$17,0))),"")) | X15: =IF($A15="","",IFERROR(IF(INDEX('Cierre'!$F$6:$F$17,MATCH($A15,'Cierre'!$B$6:$B$17,0))="","",INDEX('Cierre'!$F$6:$F$17,MATCH($A15,'Cierre'!$B$6:$B$17,0))),"")) | Y15: =IF($A15="","",IF(W15="","Sin cierre todavía",IF(AND(W15>=9,N(G15)>=0.6),"Testimonio: pídeselo",IF(W15<=6,"Riesgo: entender por qué","Seguir midiendo"))))
A16: =IF(Perfil!$A$10="","",Perfil!$A$10) | B16: =IF(OR($A16="",Perfil!$B$10="no está en Lalan"),"",Perfil!$B$10) | C16: =IF($A16="","",IF(Perfil!$Q$10="","—",Perfil!$Q$10)) | D16: =IF($B16="","",COUNTIFS('Datos diario'!$C:$C,$B16)) | E16: =IF($B16="","",COUNTIFS('Datos diario'!$C:$C,$B16,'Datos diario'!$U:$U,">0")) | F16: =IF($B16="","",SUMIFS('Datos diario'!$E:$E,'Datos diario'!$C:$C,$B16)) | G16: =IF($B16="","",IFERROR(SUMIFS('Datos diario'!$F:$F,'Datos diario'!$C:$C,$B16)/(SUMIFS('Datos diario'!$F:$F,'Datos diario'!$C:$C,$B16)+SUMIFS('Datos diario'!$G:$G,'Datos diario'!$C:$C,$B16)),"")) | H16: =IF($B16="","",IFERROR(SUMIFS('Datos diario'!$I:$I,'Datos diario'!$C:$C,$B16)/SUMIFS('Datos diario'!$E:$E,'Datos diario'!$C:$C,$B16)*100,"")) | I16: =IF($B16="","",IFERROR(AVERAGEIFS('Datos diario'!$M:$M,'Datos diario'!$C:$C,$B16,'Datos diario'!$L:$L,">0"),"")) | J16: =IF($A16="","",IFERROR(IF(INDEX('Línea base'!$F$6:$F$17,MATCH($A16,'Línea base'!$A$6:$A$17,0))="","",INDEX('Línea base'!$F$6:$F$17,MATCH($A16,'Línea base'!$A$6:$A$17,0))),"")) | K16: =IF($B16="","",SUMIFS('Datos diario'!$P:$P,'Datos diario'!$C:$C,$B16)) | L16: =IF($B16="","",IFERROR(SUMIFS('Datos diario'!$P:$P,'Datos diario'!$C:$C,$B16)/SUMIFS('Datos diario'!$O:$O,'Datos diario'!$C:$C,$B16),"")) | M16: =IF($B16="","",IFERROR(SUMIFS('Datos diario'!$T:$T,'Datos diario'!$C:$C,$B16)/SUMIFS('Datos diario'!$Q:$Q,'Datos diario'!$C:$C,$B16),"")) | N16: =IF($A16="","",IFERROR(IF(INDEX('Línea base'!$H$6:$H$17,MATCH($A16,'Línea base'!$A$6:$A$17,0))="","",INDEX('Línea base'!$H$6:$H$17,MATCH($A16,'Línea base'!$A$6:$A$17,0))),"")) | O16: =IF($B16="","",IFERROR(SUMIFS('Datos diario'!$U:$U,'Datos diario'!$C:$C,$B16)/E16,"")) | P16: =IF($B16="","",SUMIFS('Datos diario'!$X:$X,'Datos diario'!$C:$C,$B16)) | Q16: =IF($B16="","",IFERROR(SUMIFS('Datos diario'!$AB:$AB,'Datos diario'!$C:$C,$B16)/SUMIFS('Datos diario'!$AA:$AA,'Datos diario'!$C:$C,$B16),"")) | R16: =IF($A16="","",IFERROR(AVERAGEIFS('Revisión semanal'!$L$6:$L$205,'Revisión semanal'!$B$6:$B$205,$A16),"")) | S16: =IF($A16="","",IFERROR(AVERAGEIFS('Revisión semanal'!$M$6:$M$205,'Revisión semanal'!$B$6:$B$205,$A16),"")) | T16: =IF($A16="","",IFERROR(IF(INDEX('Línea base'!$D$6:$D$17,MATCH($A16,'Línea base'!$A$6:$A$17,0))="","",INDEX('Línea base'!$D$6:$D$17,MATCH($A16,'Línea base'!$A$6:$A$17,0))),"")) | U16: =IF($A16="","",IFERROR(AVERAGEIFS('Clientas'!$G$6:$G$405,'Clientas'!$B$6:$B$405,$A16),"")) | V16: =IF($A16="","",IFERROR(AVERAGEIFS('Equipo'!$D$6:$D$155,'Equipo'!$B$6:$B$155,$A16),"")) | W16: =IF($A16="","",IFERROR(IF(INDEX('Cierre'!$C$6:$C$17,MATCH($A16,'Cierre'!$B$6:$B$17,0))="","",INDEX('Cierre'!$C$6:$C$17,MATCH($A16,'Cierre'!$B$6:$B$17,0))),"")) | X16: =IF($A16="","",IFERROR(IF(INDEX('Cierre'!$F$6:$F$17,MATCH($A16,'Cierre'!$B$6:$B$17,0))="","",INDEX('Cierre'!$F$6:$F$17,MATCH($A16,'Cierre'!$B$6:$B$17,0))),"")) | Y16: =IF($A16="","",IF(W16="","Sin cierre todavía",IF(AND(W16>=9,N(G16)>=0.6),"Testimonio: pídeselo",IF(W16<=6,"Riesgo: entender por qué","Seguir midiendo"))))
A17: =IF(Perfil!$A$11="","",Perfil!$A$11) | B17: =IF(OR($A17="",Perfil!$B$11="no está en Lalan"),"",Perfil!$B$11) | C17: =IF($A17="","",IF(Perfil!$Q$11="","—",Perfil!$Q$11)) | D17: =IF($B17="","",COUNTIFS('Datos diario'!$C:$C,$B17)) | E17: =IF($B17="","",COUNTIFS('Datos diario'!$C:$C,$B17,'Datos diario'!$U:$U,">0")) | F17: =IF($B17="","",SUMIFS('Datos diario'!$E:$E,'Datos diario'!$C:$C,$B17)) | G17: =IF($B17="","",IFERROR(SUMIFS('Datos diario'!$F:$F,'Datos diario'!$C:$C,$B17)/(SUMIFS('Datos diario'!$F:$F,'Datos diario'!$C:$C,$B17)+SUMIFS('Datos diario'!$G:$G,'Datos diario'!$C:$C,$B17)),"")) | H17: =IF($B17="","",IFERROR(SUMIFS('Datos diario'!$I:$I,'Datos diario'!$C:$C,$B17)/SUMIFS('Datos diario'!$E:$E,'Datos diario'!$C:$C,$B17)*100,"")) | I17: =IF($B17="","",IFERROR(AVERAGEIFS('Datos diario'!$M:$M,'Datos diario'!$C:$C,$B17,'Datos diario'!$L:$L,">0"),"")) | J17: =IF($A17="","",IFERROR(IF(INDEX('Línea base'!$F$6:$F$17,MATCH($A17,'Línea base'!$A$6:$A$17,0))="","",INDEX('Línea base'!$F$6:$F$17,MATCH($A17,'Línea base'!$A$6:$A$17,0))),"")) | K17: =IF($B17="","",SUMIFS('Datos diario'!$P:$P,'Datos diario'!$C:$C,$B17)) | L17: =IF($B17="","",IFERROR(SUMIFS('Datos diario'!$P:$P,'Datos diario'!$C:$C,$B17)/SUMIFS('Datos diario'!$O:$O,'Datos diario'!$C:$C,$B17),"")) | M17: =IF($B17="","",IFERROR(SUMIFS('Datos diario'!$T:$T,'Datos diario'!$C:$C,$B17)/SUMIFS('Datos diario'!$Q:$Q,'Datos diario'!$C:$C,$B17),"")) | N17: =IF($A17="","",IFERROR(IF(INDEX('Línea base'!$H$6:$H$17,MATCH($A17,'Línea base'!$A$6:$A$17,0))="","",INDEX('Línea base'!$H$6:$H$17,MATCH($A17,'Línea base'!$A$6:$A$17,0))),"")) | O17: =IF($B17="","",IFERROR(SUMIFS('Datos diario'!$U:$U,'Datos diario'!$C:$C,$B17)/E17,"")) | P17: =IF($B17="","",SUMIFS('Datos diario'!$X:$X,'Datos diario'!$C:$C,$B17)) | Q17: =IF($B17="","",IFERROR(SUMIFS('Datos diario'!$AB:$AB,'Datos diario'!$C:$C,$B17)/SUMIFS('Datos diario'!$AA:$AA,'Datos diario'!$C:$C,$B17),"")) | R17: =IF($A17="","",IFERROR(AVERAGEIFS('Revisión semanal'!$L$6:$L$205,'Revisión semanal'!$B$6:$B$205,$A17),"")) | S17: =IF($A17="","",IFERROR(AVERAGEIFS('Revisión semanal'!$M$6:$M$205,'Revisión semanal'!$B$6:$B$205,$A17),"")) | T17: =IF($A17="","",IFERROR(IF(INDEX('Línea base'!$D$6:$D$17,MATCH($A17,'Línea base'!$A$6:$A$17,0))="","",INDEX('Línea base'!$D$6:$D$17,MATCH($A17,'Línea base'!$A$6:$A$17,0))),"")) | U17: =IF($A17="","",IFERROR(AVERAGEIFS('Clientas'!$G$6:$G$405,'Clientas'!$B$6:$B$405,$A17),"")) | V17: =IF($A17="","",IFERROR(AVERAGEIFS('Equipo'!$D$6:$D$155,'Equipo'!$B$6:$B$155,$A17),"")) | W17: =IF($A17="","",IFERROR(IF(INDEX('Cierre'!$C$6:$C$17,MATCH($A17,'Cierre'!$B$6:$B$17,0))="","",INDEX('Cierre'!$C$6:$C$17,MATCH($A17,'Cierre'!$B$6:$B$17,0))),"")) | X17: =IF($A17="","",IFERROR(IF(INDEX('Cierre'!$F$6:$F$17,MATCH($A17,'Cierre'!$B$6:$B$17,0))="","",INDEX('Cierre'!$F$6:$F$17,MATCH($A17,'Cierre'!$B$6:$B$17,0))),"")) | Y17: =IF($A17="","",IF(W17="","Sin cierre todavía",IF(AND(W17>=9,N(G17)>=0.6),"Testimonio: pídeselo",IF(W17<=6,"Riesgo: entender por qué","Seguir midiendo"))))
A18: =IF(Perfil!$A$12="","",Perfil!$A$12) | B18: =IF(OR($A18="",Perfil!$B$12="no está en Lalan"),"",Perfil!$B$12) | C18: =IF($A18="","",IF(Perfil!$Q$12="","—",Perfil!$Q$12)) | D18: =IF($B18="","",COUNTIFS('Datos diario'!$C:$C,$B18)) | E18: =IF($B18="","",COUNTIFS('Datos diario'!$C:$C,$B18,'Datos diario'!$U:$U,">0")) | F18: =IF($B18="","",SUMIFS('Datos diario'!$E:$E,'Datos diario'!$C:$C,$B18)) | G18: =IF($B18="","",IFERROR(SUMIFS('Datos diario'!$F:$F,'Datos diario'!$C:$C,$B18)/(SUMIFS('Datos diario'!$F:$F,'Datos diario'!$C:$C,$B18)+SUMIFS('Datos diario'!$G:$G,'Datos diario'!$C:$C,$B18)),"")) | H18: =IF($B18="","",IFERROR(SUMIFS('Datos diario'!$I:$I,'Datos diario'!$C:$C,$B18)/SUMIFS('Datos diario'!$E:$E,'Datos diario'!$C:$C,$B18)*100,"")) | I18: =IF($B18="","",IFERROR(AVERAGEIFS('Datos diario'!$M:$M,'Datos diario'!$C:$C,$B18,'Datos diario'!$L:$L,">0"),"")) | J18: =IF($A18="","",IFERROR(IF(INDEX('Línea base'!$F$6:$F$17,MATCH($A18,'Línea base'!$A$6:$A$17,0))="","",INDEX('Línea base'!$F$6:$F$17,MATCH($A18,'Línea base'!$A$6:$A$17,0))),"")) | K18: =IF($B18="","",SUMIFS('Datos diario'!$P:$P,'Datos diario'!$C:$C,$B18)) | L18: =IF($B18="","",IFERROR(SUMIFS('Datos diario'!$P:$P,'Datos diario'!$C:$C,$B18)/SUMIFS('Datos diario'!$O:$O,'Datos diario'!$C:$C,$B18),"")) | M18: =IF($B18="","",IFERROR(SUMIFS('Datos diario'!$T:$T,'Datos diario'!$C:$C,$B18)/SUMIFS('Datos diario'!$Q:$Q,'Datos diario'!$C:$C,$B18),"")) | N18: =IF($A18="","",IFERROR(IF(INDEX('Línea base'!$H$6:$H$17,MATCH($A18,'Línea base'!$A$6:$A$17,0))="","",INDEX('Línea base'!$H$6:$H$17,MATCH($A18,'Línea base'!$A$6:$A$17,0))),"")) | O18: =IF($B18="","",IFERROR(SUMIFS('Datos diario'!$U:$U,'Datos diario'!$C:$C,$B18)/E18,"")) | P18: =IF($B18="","",SUMIFS('Datos diario'!$X:$X,'Datos diario'!$C:$C,$B18)) | Q18: =IF($B18="","",IFERROR(SUMIFS('Datos diario'!$AB:$AB,'Datos diario'!$C:$C,$B18)/SUMIFS('Datos diario'!$AA:$AA,'Datos diario'!$C:$C,$B18),"")) | R18: =IF($A18="","",IFERROR(AVERAGEIFS('Revisión semanal'!$L$6:$L$205,'Revisión semanal'!$B$6:$B$205,$A18),"")) | S18: =IF($A18="","",IFERROR(AVERAGEIFS('Revisión semanal'!$M$6:$M$205,'Revisión semanal'!$B$6:$B$205,$A18),"")) | T18: =IF($A18="","",IFERROR(IF(INDEX('Línea base'!$D$6:$D$17,MATCH($A18,'Línea base'!$A$6:$A$17,0))="","",INDEX('Línea base'!$D$6:$D$17,MATCH($A18,'Línea base'!$A$6:$A$17,0))),"")) | U18: =IF($A18="","",IFERROR(AVERAGEIFS('Clientas'!$G$6:$G$405,'Clientas'!$B$6:$B$405,$A18),"")) | V18: =IF($A18="","",IFERROR(AVERAGEIFS('Equipo'!$D$6:$D$155,'Equipo'!$B$6:$B$155,$A18),"")) | W18: =IF($A18="","",IFERROR(IF(INDEX('Cierre'!$C$6:$C$17,MATCH($A18,'Cierre'!$B$6:$B$17,0))="","",INDEX('Cierre'!$C$6:$C$17,MATCH($A18,'Cierre'!$B$6:$B$17,0))),"")) | X18: =IF($A18="","",IFERROR(IF(INDEX('Cierre'!$F$6:$F$17,MATCH($A18,'Cierre'!$B$6:$B$17,0))="","",INDEX('Cierre'!$F$6:$F$17,MATCH($A18,'Cierre'!$B$6:$B$17,0))),"")) | Y18: =IF($A18="","",IF(W18="","Sin cierre todavía",IF(AND(W18>=9,N(G18)>=0.6),"Testimonio: pídeselo",IF(W18<=6,"Riesgo: entender por qué","Seguir midiendo"))))
A19: =IF(Perfil!$A$13="","",Perfil!$A$13) | B19: =IF(OR($A19="",Perfil!$B$13="no está en Lalan"),"",Perfil!$B$13) | C19: =IF($A19="","",IF(Perfil!$Q$13="","—",Perfil!$Q$13)) | D19: =IF($B19="","",COUNTIFS('Datos diario'!$C:$C,$B19)) | E19: =IF($B19="","",COUNTIFS('Datos diario'!$C:$C,$B19,'Datos diario'!$U:$U,">0")) | F19: =IF($B19="","",SUMIFS('Datos diario'!$E:$E,'Datos diario'!$C:$C,$B19)) | G19: =IF($B19="","",IFERROR(SUMIFS('Datos diario'!$F:$F,'Datos diario'!$C:$C,$B19)/(SUMIFS('Datos diario'!$F:$F,'Datos diario'!$C:$C,$B19)+SUMIFS('Datos diario'!$G:$G,'Datos diario'!$C:$C,$B19)),"")) | H19: =IF($B19="","",IFERROR(SUMIFS('Datos diario'!$I:$I,'Datos diario'!$C:$C,$B19)/SUMIFS('Datos diario'!$E:$E,'Datos diario'!$C:$C,$B19)*100,"")) | I19: =IF($B19="","",IFERROR(AVERAGEIFS('Datos diario'!$M:$M,'Datos diario'!$C:$C,$B19,'Datos diario'!$L:$L,">0"),"")) | J19: =IF($A19="","",IFERROR(IF(INDEX('Línea base'!$F$6:$F$17,MATCH($A19,'Línea base'!$A$6:$A$17,0))="","",INDEX('Línea base'!$F$6:$F$17,MATCH($A19,'Línea base'!$A$6:$A$17,0))),"")) | K19: =IF($B19="","",SUMIFS('Datos diario'!$P:$P,'Datos diario'!$C:$C,$B19)) | L19: =IF($B19="","",IFERROR(SUMIFS('Datos diario'!$P:$P,'Datos diario'!$C:$C,$B19)/SUMIFS('Datos diario'!$O:$O,'Datos diario'!$C:$C,$B19),"")) | M19: =IF($B19="","",IFERROR(SUMIFS('Datos diario'!$T:$T,'Datos diario'!$C:$C,$B19)/SUMIFS('Datos diario'!$Q:$Q,'Datos diario'!$C:$C,$B19),"")) | N19: =IF($A19="","",IFERROR(IF(INDEX('Línea base'!$H$6:$H$17,MATCH($A19,'Línea base'!$A$6:$A$17,0))="","",INDEX('Línea base'!$H$6:$H$17,MATCH($A19,'Línea base'!$A$6:$A$17,0))),"")) | O19: =IF($B19="","",IFERROR(SUMIFS('Datos diario'!$U:$U,'Datos diario'!$C:$C,$B19)/E19,"")) | P19: =IF($B19="","",SUMIFS('Datos diario'!$X:$X,'Datos diario'!$C:$C,$B19)) | Q19: =IF($B19="","",IFERROR(SUMIFS('Datos diario'!$AB:$AB,'Datos diario'!$C:$C,$B19)/SUMIFS('Datos diario'!$AA:$AA,'Datos diario'!$C:$C,$B19),"")) | R19: =IF($A19="","",IFERROR(AVERAGEIFS('Revisión semanal'!$L$6:$L$205,'Revisión semanal'!$B$6:$B$205,$A19),"")) | S19: =IF($A19="","",IFERROR(AVERAGEIFS('Revisión semanal'!$M$6:$M$205,'Revisión semanal'!$B$6:$B$205,$A19),"")) | T19: =IF($A19="","",IFERROR(IF(INDEX('Línea base'!$D$6:$D$17,MATCH($A19,'Línea base'!$A$6:$A$17,0))="","",INDEX('Línea base'!$D$6:$D$17,MATCH($A19,'Línea base'!$A$6:$A$17,0))),"")) | U19: =IF($A19="","",IFERROR(AVERAGEIFS('Clientas'!$G$6:$G$405,'Clientas'!$B$6:$B$405,$A19),"")) | V19: =IF($A19="","",IFERROR(AVERAGEIFS('Equipo'!$D$6:$D$155,'Equipo'!$B$6:$B$155,$A19),"")) | W19: =IF($A19="","",IFERROR(IF(INDEX('Cierre'!$C$6:$C$17,MATCH($A19,'Cierre'!$B$6:$B$17,0))="","",INDEX('Cierre'!$C$6:$C$17,MATCH($A19,'Cierre'!$B$6:$B$17,0))),"")) | X19: =IF($A19="","",IFERROR(IF(INDEX('Cierre'!$F$6:$F$17,MATCH($A19,'Cierre'!$B$6:$B$17,0))="","",INDEX('Cierre'!$F$6:$F$17,MATCH($A19,'Cierre'!$B$6:$B$17,0))),"")) | Y19: =IF($A19="","",IF(W19="","Sin cierre todavía",IF(AND(W19>=9,N(G19)>=0.6),"Testimonio: pídeselo",IF(W19<=6,"Riesgo: entender por qué","Seguir midiendo"))))
A20: =IF(Perfil!$A$14="","",Perfil!$A$14) | B20: =IF(OR($A20="",Perfil!$B$14="no está en Lalan"),"",Perfil!$B$14) | C20: =IF($A20="","",IF(Perfil!$Q$14="","—",Perfil!$Q$14)) | D20: =IF($B20="","",COUNTIFS('Datos diario'!$C:$C,$B20)) | E20: =IF($B20="","",COUNTIFS('Datos diario'!$C:$C,$B20,'Datos diario'!$U:$U,">0")) | F20: =IF($B20="","",SUMIFS('Datos diario'!$E:$E,'Datos diario'!$C:$C,$B20)) | G20: =IF($B20="","",IFERROR(SUMIFS('Datos diario'!$F:$F,'Datos diario'!$C:$C,$B20)/(SUMIFS('Datos diario'!$F:$F,'Datos diario'!$C:$C,$B20)+SUMIFS('Datos diario'!$G:$G,'Datos diario'!$C:$C,$B20)),"")) | H20: =IF($B20="","",IFERROR(SUMIFS('Datos diario'!$I:$I,'Datos diario'!$C:$C,$B20)/SUMIFS('Datos diario'!$E:$E,'Datos diario'!$C:$C,$B20)*100,"")) | I20: =IF($B20="","",IFERROR(AVERAGEIFS('Datos diario'!$M:$M,'Datos diario'!$C:$C,$B20,'Datos diario'!$L:$L,">0"),"")) | J20: =IF($A20="","",IFERROR(IF(INDEX('Línea base'!$F$6:$F$17,MATCH($A20,'Línea base'!$A$6:$A$17,0))="","",INDEX('Línea base'!$F$6:$F$17,MATCH($A20,'Línea base'!$A$6:$A$17,0))),"")) | K20: =IF($B20="","",SUMIFS('Datos diario'!$P:$P,'Datos diario'!$C:$C,$B20)) | L20: =IF($B20="","",IFERROR(SUMIFS('Datos diario'!$P:$P,'Datos diario'!$C:$C,$B20)/SUMIFS('Datos diario'!$O:$O,'Datos diario'!$C:$C,$B20),"")) | M20: =IF($B20="","",IFERROR(SUMIFS('Datos diario'!$T:$T,'Datos diario'!$C:$C,$B20)/SUMIFS('Datos diario'!$Q:$Q,'Datos diario'!$C:$C,$B20),"")) | N20: =IF($A20="","",IFERROR(IF(INDEX('Línea base'!$H$6:$H$17,MATCH($A20,'Línea base'!$A$6:$A$17,0))="","",INDEX('Línea base'!$H$6:$H$17,MATCH($A20,'Línea base'!$A$6:$A$17,0))),"")) | O20: =IF($B20="","",IFERROR(SUMIFS('Datos diario'!$U:$U,'Datos diario'!$C:$C,$B20)/E20,"")) | P20: =IF($B20="","",SUMIFS('Datos diario'!$X:$X,'Datos diario'!$C:$C,$B20)) | Q20: =IF($B20="","",IFERROR(SUMIFS('Datos diario'!$AB:$AB,'Datos diario'!$C:$C,$B20)/SUMIFS('Datos diario'!$AA:$AA,'Datos diario'!$C:$C,$B20),"")) | R20: =IF($A20="","",IFERROR(AVERAGEIFS('Revisión semanal'!$L$6:$L$205,'Revisión semanal'!$B$6:$B$205,$A20),"")) | S20: =IF($A20="","",IFERROR(AVERAGEIFS('Revisión semanal'!$M$6:$M$205,'Revisión semanal'!$B$6:$B$205,$A20),"")) | T20: =IF($A20="","",IFERROR(IF(INDEX('Línea base'!$D$6:$D$17,MATCH($A20,'Línea base'!$A$6:$A$17,0))="","",INDEX('Línea base'!$D$6:$D$17,MATCH($A20,'Línea base'!$A$6:$A$17,0))),"")) | U20: =IF($A20="","",IFERROR(AVERAGEIFS('Clientas'!$G$6:$G$405,'Clientas'!$B$6:$B$405,$A20),"")) | V20: =IF($A20="","",IFERROR(AVERAGEIFS('Equipo'!$D$6:$D$155,'Equipo'!$B$6:$B$155,$A20),"")) | W20: =IF($A20="","",IFERROR(IF(INDEX('Cierre'!$C$6:$C$17,MATCH($A20,'Cierre'!$B$6:$B$17,0))="","",INDEX('Cierre'!$C$6:$C$17,MATCH($A20,'Cierre'!$B$6:$B$17,0))),"")) | X20: =IF($A20="","",IFERROR(IF(INDEX('Cierre'!$F$6:$F$17,MATCH($A20,'Cierre'!$B$6:$B$17,0))="","",INDEX('Cierre'!$F$6:$F$17,MATCH($A20,'Cierre'!$B$6:$B$17,0))),"")) | Y20: =IF($A20="","",IF(W20="","Sin cierre todavía",IF(AND(W20>=9,N(G20)>=0.6),"Testimonio: pídeselo",IF(W20<=6,"Riesgo: entender por qué","Seguir midiendo"))))
