Workbook

Sheet Supuestos
A1: Lalan AI · Supuestos del modelo de costos
A2: Cambia solo las celdas en AZUL con fondo amarillo. Todo lo demás se calcula solo. Precios de proveedores verificados el 26 de septiembre de 2026 (ver hoja Fuentes).
A4: Moneda, impuestos y cobro
A5: Supuesto | B5: Valor | C5: Unidad | D5: De dónde sale / nota
A6: Tasa del dólar (venta) | B6: 59.4618 | C6: RD$ por US$ | D6: Banco Central RD, tasa de venta del 24-sep-2026 (vigente hasta el 25-sep). Actualízala al negociar.
A7: Colchón cambiario | B7: 0.08 | C7: % | D7: Protección por si el peso se deprecia mientras el precio en pesos queda fijo. Todos los costos en dólares se multiplican por (1 + colchón).
A8: ITBIS | B8: 0.18 | C8: % | D8: Impuesto a la venta en RD.
A9: ¿El precio del plan ya incluye ITBIS? (1 = sí, 0 = no) | B9: 1 | C9: 1 / 0 | D9: Con 1, de cada RD$ 118 cobrados, RD$ 18 son del fisco. Pon 0 si facturas ITBIS aparte o si no estás obligado (consúltalo con tu contador).
A10: Comisión del cobro (tarjeta, pasarela o transferencia) | B10: 0.04 | C10: % del precio | D10: Estimado. Ajusta a tu medio de cobro real (Azul, CardNet, PayPal, Stripe…). Transferencia bancaria ≈ 0 %.
A11: Margen que quieres ganar sobre el ingreso neto | B11: 0.4 | C11: % | D11: Se usa para calcular el precio mínimo sugerido de cada plan.
A12: Inteligencia artificial (OpenRouter · gpt-4.1-mini)
A13: Supuesto | B13: Valor | C13: Unidad | D13: De dónde sale / nota
A14: Precio de entrada | B14: 0.4 | C14: US$ / millón de tokens | D14: OpenRouter, openai/gpt-4.1-mini: US$ 0.40 entrada · US$ 1.60 salida por millón.
A15: Precio de salida | B15: 1.6 | C15: US$ / millón de tokens | D15: Ídem.
A16: Precio de entrada en caché | B16: 0.1 | C16: US$ / millón de tokens | D16: ESTIMADO: OpenAI cobra ~25 % del precio por la parte del prompt que se repite (caché). Verifica en OpenRouter.
A17: Tokens de entrada por llamada al modelo | B17: 6500 | C17: tokens | D17: Medido el 26-sep-2026 con el prompt nuevo, en un salón de 22 servicios y 6 especialistas: mensaje de sistema 3.800 (3.150 fijos + 650 que cambian) + 12 herramientas 1.400 + mensaje y resultados de herramientas ~1.300. Con unos 50 servicios, súmale ~800. Compáralo con la columna Tokens de la actividad de OpenRouter.
A18: Tokens de salida por llamada | B18: 250 | C18: tokens | D18: Una respuesta de chat o una llamada a herramienta.
A19: Llamadas al modelo cada vez que Lalan contesta | B19: 2 | C19: llamadas | D19: Una pregunta simple = 1; agendar = 3 o 4 (consulta, agenda, respuesta). 2 es un promedio prudente.
A20: Parte de la entrada que va en caché | B20: 0.55 | C20: % | D20: ESTIMADO. Desde el 26-sep el prompt pone primero lo fijo (reglas, servicios, herramientas ≈ 78 % de la entrada) y al final lo que cambia. La 2.ª y 3.ª llamada de cada respuesta casi siempre sale de caché; la 1.ª, solo si ese salón tuvo otro mensaje en los últimos ~5-10 min. Salón con poco movimiento ≈ 40 %; salón con mucho ≈ 65 %. Verifícalo en OpenRouter (Activity → cached tokens).
A21: Mensajes de clientas que llegan en ráfaga y se contestan juntos | B21: 0.2 | C21: % | D21: ESTIMADO. "hola" · "quería una cita" · "para mañana" = 3 mensajes, 1 respuesta. Lalan espera 7 s por si la clienta sigue escribiendo (se cambia en el nodo Configuración Lalan de n8n). Cuéntalo tú: respuestas de Lalan ÷ mensajes de clientas en el panel de bots.
A22: Comisión de OpenRouter al recargar créditos | B22: 0.055 | C22: % | D22: ESTIMADO (~5,5 % por compra de créditos con tarjeta). Verifica en tu cuenta.
A23: → Costo de IA por mensaje de clienta | B23: =((TokensEntrada*(1-PorcCache)*PrecioEntrada+TokensEntrada*PorcCache*PrecioCache+TokensSalida*PrecioSalida)/1000000)*LlamadasPorMensaje*(1-PorcAgrupados)*(1+ComisionOpenRouter) -> 0.00325362 | C23: US$
A24: Notas de voz de las clientas (transcripción · Groq Whisper)
A25: Supuesto | B25: Valor | C25: Unidad | D25: De dónde sale / nota
A26: Precio de transcripción | B26: 0.111 | C26: US$ / hora de audio | D26: Groq, whisper-large-v3.
A27: Duración promedio de una nota de voz | B27: 20 | C27: segundos | D27: Supuesto.
A28: Mínimo facturable por audio | B28: 10 | C28: segundos | D28: Groq cobra al menos 10 s por audio.
A29: Mensajes de clientas que llegan como nota de voz | B29: 0.3 | C29: % | D29: Supuesto; en RD se usan mucho.
A30: → Costo de transcripción por mensaje de clienta (promedio) | B30: =PorcNotasVoz*MAX(SegundosNota,MinimoSegundos)/3600*PrecioTranscripcion -> 0.000185 | C30: US$
A31: WhatsApp (Meta) · desde el 1 de octubre de 2026
A32: Supuesto | B32: Valor | C32: Unidad | D32: De dónde sale / nota
A33: Tarifa por mensaje de servicio (respuestas) pasado el gratis | B33: 0.0113 | C33: US$ / mensaje | D33: Resto de América Latina (RD está en este grupo). Desde el 1-oct-2026 Meta cobra las respuestas de servicio pasadas las 1.000 gratis por número al mes.
A34: Mensajes de servicio gratis por número al mes | B34: 1000 | C34: mensajes | D34: Por NÚMERO de WhatsApp (cada salón tiene el suyo). No se acumulan.
A35: Tarifa de plantilla de utilidad (aviso a la dueña) | B35: 0.0113 | C35: US$ / mensaje | D35: Misma tarifa. Gratis si la dueña escribió a ese número en las últimas 24 h; aquí se asume que siempre se paga.
A36: Mensajes que manda Lalan cada vez que contesta | B36: 1.2 | C36: mensajes | D36: A veces responde en dos mensajes (la cita y luego el Lounge).
A37: → Mensajes que salen por cada mensaje de una clienta | B37: =MensajesPorRespuesta*(1-PorcAgrupados) -> 0.96 | C37: mensajes | D37: Los mensajes en ráfaga se contestan juntos: una sola respuesta.
A38: Voz de la dueña (ElevenLabs · clonación de voz)
A39: Supuesto | B39: Valor | C39: Unidad | D39: De dónde sale / nota
A40: Precio por cada 1.000 caracteres convertidos a voz | B40: 0.06 | C40: US$ | D40: ElevenLabs API, modelos Flash/Turbo: US$ 0.06 por 1.000 caracteres. Multilingual (mejor calidad): US$ 0.12.
A41: Caracteres por respuesta hablada | B41: 180 | C41: caracteres | D41: Una respuesta de chat típica (~30 palabras).
...

Sheet Planes
A1: Lalan AI · Planes: costo, precio y margen por salón al mes
A2: Azul con fondo amarillo = lo negocias tú. Negro = se calcula. Todo en pesos salvo donde dice US$.
A4: Concepto | B4: Esencial | C4: Salón | D4: Lounge | E4: Nota
A5: Lo que negocias
A6: Precio mensual al salón | B6: 495 | C6: 1490 | D6: 2990 | E6: Lo que paga la dueña. Si IncluyeITBIS = 1, este precio ya lleva el ITBIS dentro.
A7: Mensajes de clientas incluidos al mes | B7: 200 | C7: 1000 | D7: 2000 | E7: Mensajes que Lalan atiende. Pasado el límite: paquete extra o sube de plan.
A8: Uso esperado del límite | B8: 0.7 | C8: 0.6 | D8: 0.6 | E8: Casi nadie usa el 100 %. Para el peor caso, pon 100 %.
A9: Mensajes que el equipo escribe desde la app al mes | B9: 40 | C9: 200 | D9: 500 | E9: También salen por la API de WhatsApp y cuentan para las 1.000 gratis.
A10: Respuestas de Lalan con la voz de la dueña | B10: 0 | C10: 0 | D10: 0.2 | E10: Parte de las respuestas que se mandan como audio. Solo en el plan Lounge.
A11: Avisos a la dueña al mes (plantilla) | B11: 10 | C11: 20 | D11: 40 | E11: Chats que pasan a una persona + citas sin especialista.
A12: Horas de soporte al mes | B12: 0.1 | C12: 0.5 | D12: 1 | E12: Tu tiempo atendiendo dudas y cambios.
A13: ¿Meta se lo cobra al salón directamente? (1 = sí, 0 = lo pagas tú) | B13: 1 | C13: 1 | D13: 1 | E13: Recomendado 1: cada salón conecta su número y pone SU tarjeta en Meta. Así el costo de WhatsApp nunca es tuyo.
A14: Costos del mes (US$)
A15: Mensajes de clientas atendidos | B15: =B7*B8 -> 140 | C15: =C7*C8 -> 600 | D15: =D7*D8 -> 1200
A16: Inteligencia artificial | B16: =B15*CostoIAPorMensaje -> 0.4555068 | C16: =C15*CostoIAPorMensaje -> 1.952172 | D16: =D15*CostoIAPorMensaje -> 3.904344
A17: Transcripción de notas de voz | B17: =B15*CostoTranscripcionPorMensaje -> 0.0259 | C17: =C15*CostoTranscripcionPorMensaje -> 0.111 | D17: =D15*CostoTranscripcionPorMensaje -> 0.222
A18: Mensajes que salen por WhatsApp (cantidad) | B18: =B15*RespuestasPorMensaje+B9 -> 174.4 | C18: =C15*RespuestasPorMensaje+C9 -> 776 | D18: =D15*RespuestasPorMensaje+D9 -> 1652
A19: WhatsApp: respuestas pasadas las 1.000 gratis | B19: =MAX(0,B18-GratisPorNumero)*TarifaServicio*(1-B13) -> 0 | C19: =MAX(0,C18-GratisPorNumero)*TarifaServicio*(1-C13) -> 0 | D19: =MAX(0,D18-GratisPorNumero)*TarifaServicio*(1-D13) -> 0 | E19: 0 si Meta se lo cobra al salón.
A20: WhatsApp: avisos a la dueña | B20: =B11*TarifaUtilidad*(1-B13) -> 0 | C20: =C11*TarifaUtilidad*(1-C13) -> 0 | D20: =D11*TarifaUtilidad*(1-D13) -> 0
A21: Voz de la dueña | B21: =B15*RespuestasPorMensaje*B10*CostoVozPorRespuesta -> 0 | C21: =C15*RespuestasPorMensaje*C10*CostoVozPorRespuesta -> 0 | D21: =D15*RespuestasPorMensaje*D10*CostoVozPorRespuesta -> 2.48832
A22: Costo variable | B22: =B16+B17+B19+B20+B21 -> 0.4814068 | C22: =C16+C17+C19+C20+C21 -> 2.063172 | D22: =D16+D17+D19+D20+D21 -> 6.614664
A23: Parte de los costos fijos | B23: =FijoPorSalon -> 2.4 | C23: =FijoPorSalon -> 2.4 | D23: =FijoPorSalon -> 2.4 | E23: Fijos ÷ salones activos (hoja Supuestos).
A24: Costo total en dólares | B24: =B22+B23 -> 2.8814068 | C24: =C22+C23 -> 4.463172 | D24: =D22+D23 -> 9.014664
A25: Resultado del mes (RD$)
A26: Costos en dólares, pasados a pesos (con colchón) | B26: =B24*FactorCambio -> 185.04033 | C26: =C24*FactorCambio -> 286.6193 | D26: =D24*FactorCambio -> 578.9104
A27: Soporte | B27: =B12*CostoHoraSoporte -> 40 | C27: =C12*CostoHoraSoporte -> 200 | D27: =D12*CostoHoraSoporte -> 400
A28: COSTO TOTAL | B28: =B26+B27 -> 225.04033 | C28: =C26+C27 -> 486.6193 | D28: =D26+D27 -> 978.9104
A29: Ingreso neto (sin ITBIS ni comisión) | B29: =B6*FactorNeto -> 402.71186 | C29: =C6*FactorNeto -> 1212.2034 | D29: =D6*FactorNeto -> 2432.5424
A30: GANANCIA | B30: =B29-B28 -> 177.67154 | C30: =C29-C28 -> 725.58409 | D30: =D29-D28 -> 1453.632
A31: Margen sobre el ingreso neto | B31: =IF(B29>0,B30/B29,0) -> 0.44118774 | C31: =IF(C29>0,C30/C29,0) -> 0.59856629 | D31: =IF(D29>0,D30/D29,0) -> 0.59757725
A32: Precio mínimo sugerido (para el margen objetivo) | B32: =IF((1-MargenObjetivo)*FactorNeto>0,B28/((1-MargenObjetivo)*FactorNeto),0) -> 461.02011 | C32: =IF((1-MargenObjetivo)*FactorNeto>0,C28/((1-MargenObjetivo)*FactorNeto),0) -> 996.89371 | D32: =IF((1-MargenObjetivo)*FactorNeto>0,D28/((1-MargenObjetivo)*FactorNeto),0) -> 2005.4067 | E32: Lo menos que deberías cobrar para ganar el margen objetivo, con estos supuestos.
A33: Costo por mensaje de clienta atendido | B33: =IF(B15>0,B28/B15,0) -> 1.6074309 | C33: =IF(C15>0,C28/C15,0) -> 0.81103217 | D33: =IF(D15>0,D28/D15,0) -> 0.81575867
A34: Lo que aporta cada salón para pagar los fijos | B34: =B29-(B22*FactorCambio+B27) -> 331.79652 | C34: =C29-(C22*FactorCambio+C27) -> 879.70908 | D34: =D29-(D22*FactorCambio+D27) -> 1607.757 | E34: Ingreso neto menos lo variable y el soporte.
A35: Salones de este plan para cubrir los fijos | B35: =IF(B34>0,FijosTotal*FactorCambio/B34,"no cubre") -> 13.935497 | C35: =IF(C34>0,FijosTotal*FactorCambio/C34,"no cubre") -> 5.2559985 | D35: =IF(D34>0,FijosTotal*FactorCambio/D34,"no cubre") -> 2.8759008 | E35: Si solo vendieras este plan: cuántos salones necesitas para no perder.
A36: Paquete extra de mensajes
A37: Mensajes del paquete extra | B37: 250 | C37: 500 | D37: 1000
A38: Costo del paquete | B38: =B37*(CostoIAPorMensaje+CostoTranscripcionPorMensaje)*FactorCambio -> 55.205964 | C38: =C37*(CostoIAPorMensaje+CostoTranscripcionPorMensaje)*FactorCambio -> 110.41193 | D38: =D37*(CostoIAPorMensaje+CostoTranscripcionPorMensaje)*FactorCambio -> 220.82386
A39: Precio sugerido del paquete (margen objetivo) | B39: =IF((1-MargenObjetivo)*FactorNeto>0,CEILING(B38/((1-MargenObjetivo)*FactorNeto),5),0) -> 115 | C39: =IF((1-MargenObjetivo)*FactorNeto>0,CEILING(C38/((1-MargenObjetivo)*FactorNeto),5),0) -> 230 | D39: =IF((1-MargenObjetivo)*FactorNeto>0,CEILING(D38/((1-MargenObjetivo)*FactorNeto),5),0) -> 455 | E39: Redondeado a 5 pesos.

Sheet Negociación
A1: Simulador para negociar con un salón
A2: Elige el plan de base y cambia lo que estés negociando. Lo demás sale de la hoja Planes y Supuestos.
A4: Lo que negocias
A5: Plan de base (1 = Esencial, 2 = Salón, 3 = Lounge) | B5: 2
A6: Plan elegido | B6: =INDEX(Planes!$B$4:$D$4,1,B5) -> Salón
A7: Precio de lista | B7: =INDEX(Planes!$B$6:$D$6,1,B5) -> 1490
A8: Descuento que ofreces | B8: 0.1 | C8: Ej.: 10 % por pago anual o por ser de las primeras.
A9: Precio negociado | B9: =B7*(1-B8) -> 1341
A10: Mensajes incluidos | B10: =INDEX(Planes!$B$7:$D$7,1,B5) -> 1000 | C10: Para cambiarlo, escribe encima un número.
A11: Uso esperado | B11: =INDEX(Planes!$B$8:$D$8,1,B5) -> 0.6
A12: Mensajes del equipo desde la app | B12: =INDEX(Planes!$B$9:$D$9,1,B5) -> 200
A13: Respuestas con la voz de la dueña | B13: =INDEX(Planes!$B$10:$D$10,1,B5) -> 0
A14: Avisos a la dueña | B14: =INDEX(Planes!$B$11:$D$11,1,B5) -> 20
A15: Horas de soporte | B15: =INDEX(Planes!$B$12:$D$12,1,B5) -> 0.5
A16: ¿Meta se lo cobra al salón? (1/0) | B16: =INDEX(Planes!$B$13:$D$13,1,B5) -> 1
A17: Resultado
A18: Mensajes atendidos | B18: =B10*B11 -> 600
A19: Mensajes que salen por WhatsApp | B19: =B18*RespuestasPorMensaje+B12 -> 776
A20: Costo variable (US$) | B20: =B18*(CostoIAPorMensaje+CostoTranscripcionPorMensaje)+MAX(0,B19-GratisPorNumero)*TarifaServicio*(1-B16)+B14*TarifaUtilidad*(1-B16)+B18*RespuestasPorMensaje*B13*CostoVozPorRespuesta -> 2.063172
A21: Costo total del mes | B21: =(B20+FijoPorSalon)*FactorCambio+B15*CostoHoraSoporte -> 486.6193
A22: Ingreso neto | B22: =B9*FactorNeto -> 1090.9831
A23: GANANCIA DEL MES | B23: =B22-B21 -> 604.36375
A24: Margen | B24: =IF(B22>0,B23/B22,0) -> 0.55396255
A25: Ganancia en un año con este salón | B25: =B23*12 -> 7252.365
A26: ¿Conviene? | B26: =IF(B24>=MargenObjetivo,"Sí: cumple el margen objetivo",IF(B23>0,"Deja ganancia, pero bajo el objetivo","No: pierdes dinero")) -> Sí: cumple el margen objetivo

Sheet Sensibilidad
A1: ¿Qué pasa con el margen si algo cambia?
A2: Margen de cada plan (hoja Planes) si el dólar sube, si la IA cuesta más, o si la caché no rinde lo esperado. Escribe tus propios factores en las celdas azules.
A4: Escenario | B4: Factor dólar | C4: Factor IA | D4: Esencial | E4: Salón | F4: Lounge
A5: Hoy (supuestos tal cual) | B5: 1 | C5: 1 | D5: =IF(Planes!B29>0,(Planes!B29-((Planes!B16*$C5+(Planes!B22-Planes!B16+Planes!B23))*FactorCambio*$B5+Planes!B27))/Planes!B29,0) -> 0.44118774 | E5: =IF(Planes!C29>0,(Planes!C29-((Planes!C16*$C5+(Planes!C22-Planes!C16+Planes!C23))*FactorCambio*$B5+Planes!C27))/Planes!C29,0) -> 0.59856629 | F5: =IF(Planes!D29>0,(Planes!D29-((Planes!D16*$C5+(Planes!D22-Planes!D16+Planes!D23))*FactorCambio*$B5+Planes!D27))/Planes!D29,0) -> 0.59757725
A6: El dólar sube 10 % | B6: 1.1 | C6: 1 | D6: =IF(Planes!B29>0,(Planes!B29-((Planes!B16*$C6+(Planes!B22-Planes!B16+Planes!B23))*FactorCambio*$B6+Planes!B27))/Planes!B29,0) -> 0.39523918 | E6: =IF(Planes!C29>0,(Planes!C29-((Planes!C16*$C6+(Planes!C22-Planes!C16+Planes!C23))*FactorCambio*$B6+Planes!C27))/Planes!C29,0) -> 0.5749218 | F6: =IF(Planes!D29>0,(Planes!D29-((Planes!D16*$C6+(Planes!D22-Planes!D16+Planes!D23))*FactorCambio*$B6+Planes!D27))/Planes!D29,0) -> 0.57377867
A7: El dólar sube 20 % | B7: 1.2 | C7: 1 | D7: =IF(Planes!B29>0,(Planes!B29-((Planes!B16*$C7+(Planes!B22-Planes!B16+Planes!B23))*FactorCambio*$B7+Planes!B27))/Planes!B29,0) -> 0.34929061 | E7: =IF(Planes!C29>0,(Planes!C29-((Planes!C16*$C7+(Planes!C22-Planes!C16+Planes!C23))*FactorCambio*$B7+Planes!C27))/Planes!C29,0) -> 0.55127731 | F7: =IF(Planes!D29>0,(Planes!D29-((Planes!D16*$C7+(Planes!D22-Planes!D16+Planes!D23))*FactorCambio*$B7+Planes!D27))/Planes!D29,0) -> 0.5499801
A8: La IA cuesta el doble (otro modelo o más llamadas) | B8: 1 | C8: 2 | D8: =IF(Planes!B29>0,(Planes!B29-((Planes!B16*$C8+(Planes!B22-Planes!B16+Planes!B23))*FactorCambio*$B8+Planes!B27))/Planes!B29,0) -> 0.36855002 | E8: =IF(Planes!C29>0,(Planes!C29-((Planes!C16*$C8+(Planes!C22-Planes!C16+Planes!C23))*FactorCambio*$B8+Planes!C27))/Planes!C29,0) -> 0.49514633 | F8: =IF(Planes!D29>0,(Planes!D29-((Planes!D16*$C8+(Planes!D22-Planes!D16+Planes!D23))*FactorCambio*$B8+Planes!D27))/Planes!D29,0) -> 0.49450317
A9: La caché no rinde (IA ~1,55× más cara) | B9: 1 | C9: 1.55 | D9: =IF(Planes!B29>0,(Planes!B29-((Planes!B16*$C9+(Planes!B22-Planes!B16+Planes!B23))*FactorCambio*$B9+Planes!B27))/Planes!B29,0) -> 0.40123699 | E9: =IF(Planes!C29>0,(Planes!C29-((Planes!C16*$C9+(Planes!C22-Planes!C16+Planes!C23))*FactorCambio*$B9+Planes!C27))/Planes!C29,0) -> 0.54168531 | F9: =IF(Planes!D29>0,(Planes!D29-((Planes!D16*$C9+(Planes!D22-Planes!D16+Planes!D23))*FactorCambio*$B9+Planes!D27))/Planes!D29,0) -> 0.5408865
A10: Peor caso: dólar +20 % e IA ×2 | B10: 1.2 | C10: 2 | D10: =IF(Planes!B29>0,(Planes!B29-((Planes!B16*$C10+(Planes!B22-Planes!B16+Planes!B23))*FactorCambio*$B10+Planes!B27))/Planes!B29,0) -> 0.26212534 | E10: =IF(Planes!C29>0,(Planes!C29-((Planes!C16*$C10+(Planes!C22-Planes!C16+Planes!C23))*FactorCambio*$B10+Planes!C27))/Planes!C29,0) -> 0.42717336 | F10: =IF(Planes!D29>0,(Planes!D29-((Planes!D16*$C10+(Planes!D22-Planes!D16+Planes!D23))*FactorCambio*$B10+Planes!D27))/Planes!D29,0) -> 0.4262912

Sheet Qué incluye
A1: Qué incluye cada plan (propuesta)
A2: Borrador para el documento comercial. Cámbialo con libertad: los costos no dependen de este texto.
A4: Función | B4: Esencial | C4: Salón | D4: Lounge
A5: Para quién | B5: Uñas y locales pequeños | C5: Salones con equipo | D5: Salones premium y spas
A6: Precio mensual | B6: =Planes!B6 -> 495 | C6: =Planes!C6 -> 1490 | D6: =Planes!D6 -> 2990
A7: Mensajes de clientas al mes | B7: =Planes!B7 -> 200 | C7: =Planes!C7 -> 1000 | D7: =Planes!D7 -> 2000
A8: Lalan responde en WhatsApp 24/7 | B8: Sí | C8: Sí | D8: Sí
A9: Entiende notas de voz | B9: Sí | C9: Sí | D9: Sí
A10: Agenda, reagenda y cancela sola | B10: Sí | C10: Sí | D10: Sí
A11: Aviso a la dueña por WhatsApp | B11: Sí | C11: Sí | D11: Sí
A12: Agenda y ficha de clientas | B12: Sí | C12: Sí | D12: Sí
A13: Especialistas y zonas | B13: — | C13: Sí | D13: Sí
A14: Lounge: música y gustos de cada clienta | B14: — | C14: Sí | D14: Sí
A15: Bienvenida con sus gustos al llegar | B15: — | C15: Sí | D15: Sí
A16: Caja y comandas | B16: — | C16: Sí | D16: Sí
A17: Informes (citas, ganancias, quién agendó) | B17: Básico | C17: Completo | D17: Completo
A18: Pantalla de turnos | B18: — | C18: Sí | D18: Sí
A19: Respuestas con la voz de la dueña | B19: — | C19: — | D19: Sí
... A23: Soporte | B23: Por WhatsApp | C23: Por WhatsApp | D23: Prioritario

Sheet Fuentes
A1: De dónde salen los precios (consultados el 26-sep-2026)
A3: Tasa del dólar (BCRD) | B3: https://acento.com.do/economia/precio-del-dolar-hoy-en-republica-dominicana-tasa-de-compra-y-venta-este-jueves-24-de-septiembre-de-2026-9758215.html
A4: gpt-4.1-mini en OpenRouter | B4: https://openrouter.ai/openai/gpt-4.1-mini
A5: Precios de WhatsApp (Meta) | B5: https://developers.facebook.com/documentation/business-messaging/whatsapp/pricing
A6: Cobro de mensajes de servicio desde 1-oct-2026 | B6: https://360dialog.com/blog/whatsapp-service-message-charging-october-2026/
A7: Groq Whisper large v3 | B7: https://console.groq.com/docs/model/whisper-large-v3
A8: ElevenLabs (planes y API) | B8: https://texttolab.com/blog/elevenlabs-pricing
A9: Railway (planes) | B9: https://docs.railway.com/pricing/plans
A11: Estimados sin fuente directa
A12: Caché de OpenAI, comisión de OpenRouter, comisión de cobro, costos de servidor, uso por salón: marcados como ESTIMADO o Supuesto en la hoja Supuestos.
